Workbook
Name _Hlk109808432: ความก้าวหน้ารายสัปดาห์!$I$14
Name acX: OFFSET(แผนการก่อสร้าง!#REF!,0,0,1,แผนการก่อสร้าง!#REF!+1)
Name acX: OFFSET(#REF!,0,0,1,#REF!+1)
Name acY: OFFSET(แผนการก่อสร้าง!#REF!,0,0,1,แผนการก่อสร้าง!#REF!+1)
Name acY: OFFSET(#REF!,0,0,1,#REF!+1)
Name conc: #REF!
Name frmwk: #REF!
Name GTotal: แผนการก่อสร้าง!$J$113
Name GTotal: #REF!
Name knd: #REF!
Name steel: #REF!
Name wmk: #REF!

Sheet แผน - ผล ประจำสัปดาห์
H1: บันทึกข้อความ | N1: ระยะเวลาปัจจุบัน | Q1: ระยะเวลาเหลือ | R1: %
H2: รายงานผลการก่อสร้าง | N2: =M42 -> 257 | Q2: =840-N2 -> 583 | R2: =Q2*100/840 -> 69.404762
F3: โครงการพัฒนาพื้นที่ชุมชนหัวรอและพื้นที่ต่อเนื่อง ตำบลหัวรอ อำเภอเมืองพิษณุโลก จังหวัดพิษณุโลก | AA3: 2567 | AH3: 2568 | AT3: 2569 | BF3: 2570
D4: จากวันที่ | E4: ถึงวันที่ | F4: สัปดาห์ที่ | G4: แผนงาน % | H4: แผนงานสะสม % | I4: ผลงาน% | J4: ผลงานสะสม % | K4: ช้าเร็วกว่าแผน% | L4: ช้าเร็วกว่าแผน% สะสม | M4: จำนวนวันสะสม | N4: ระยะเวลาดำเนินการ % | O4: ระยะเวลาคงเหลือ | P4: ระยะเวลาคงเหลือ % | Q4: ระยะเวลาดำเนินการ ควบคุมงาน | R4: ระยะเวลาดำเนินการ ควบคุมงาน (%) | S4: เวลาคงเหลือควบคุมฯ | T4: เวลาคงเหลือควบคุมฯ% | U4: หมายเหตุ | Y4: เดือน | Z4: เริ่ม | AA4: ก.ค. | AC4: ส.ค. | AD4: ก.ย. | AE4: ต.ค. | AF4: พ.ย. | AG4: ธ.ค. | AH4: ม.ค. | AI4: ก.พ. | AJ4: มี.ค. | AK4: เม.ย. | AL4: พ.ค. | AM4: มิ.ย. | AN4: ก.ค. | AO4: ส.ค. | AP4: ก.ย. | AQ4: ต.ค. | AR4: พ.ย. | AS4: ธ.ค. | AT4: ม.ค. | AU4: ก.พ. | AV4: มี.ค. | AW4: เม.ย. | AX4: พ.ค. | AY4: มิ.ย. | AZ4: ก.ค | BA4: ส.ค | BB4: ก.ย | BC4: ต.ค | BD4: พ.ย | BE4: ธ.ค. | BF4: ม.ค. | BG4: ก.พ. | BH4: มี.ค. | BI4: เม.ย. | BJ4: พ.ค. | BK4: มิ.ย. | BL4: ก.ค.
C5: TRUE | D5: 45464 | E5: 45470 | F5: 1 | G5: 0 | H5: 0 | I5: 0 | J5: 0 | K5: 0 | L5: =J5-H5 -> 0 | M5: 0 | N5: =M5/1088 -> 0 | O5: =1088-M5 -> 1088 | P5: =O5/1088 -> 1 | Q5: =E5-$D$5+1 -> 7 | R5: =Q5/1118 -> 0.0062611807 | S5: =1118-Q5 -> 1111 | T5: =S5/1118 -> 0.99373882 | W5: แผนงานต่อเดือน | AA5: 0 | AB5: =แผนการก่อสร้าง!L117 -> 0 | AP5: 0.36514641 | AQ5: 0.36514641 | AR5: 1.5617668 | AS5: 1.6219558 | AT5: 1.5573495 | AU5: 1.6024596 | AV5: 4.1165885 | AW5: 3.5594028 | AX5: 3.1989546 | AY5: 4.104194 | AZ5: 5.0097645 | BA5: 5.2589438 | BB5: 5.7627798 | BC5: 7.256855 | BD5: 5.4825347 | BE5: 6.6180233 | BF5: 6.5010543 | BG5: 6.3366979 | BH5: 6.5156319 | BI5: 7.5636949 | BJ5: 5.0482848 | BK5: 5.6624084 | BL5: 4.9303623
C6: TRUE | D6: =D5+7 -> 45471 | E6: =E5+7 -> 45477 | F6: 2 | G6: 0 | H6: =G6+H5 -> 0 | I6: 0 | J6: =I6+J5 -> 0 | K6: 0 | L6: =J6-H6 -> 0 | M6: 0 | N6: =M6/1088 -> 0 | O6: =1088-M6 -> 1088 | P6: =O6/1088 -> 1 | Q6: =E6-$D$5+1 -> 14 | R6: =Q6/1118 -> 0.012522361 | S6: =1118-Q6 -> 1104 | T6: =S6/1118 -> 0.98747764 | W6: แผนงานสะสม | AA6: 0 | AB6: =แผนการก่อสร้าง!M119 -> 0 | AP6: =แผนการก่อสร้าง!AA119 -> 0.36514641 | AQ6: =แผนการก่อสร้าง!AB119 -> 0.73029281 | AR6: =แผนการก่อสร้าง!AC119 -> 2.2920596 | AS6: =แผนการก่อสร้าง!AD119 -> 3.9140154 | AT6: =แผนการก่อสร้าง!AE119 -> 5.4713649 | AU6: =แผนการก่อสร้าง!AF119 -> 7.0738245 | AV6: =แผนการก่อสร้าง!AG119 -> 11.190413 | AW6: =แผนการก่อสร้าง!AH119 -> 14.749816 | ... BL6: =แผนการก่อสร้าง!AW119 -> 100
C7: TRUE | D7: =D6+7 -> 45478 | E7: =E6+7 -> 45484 | F7: 3 | G7: 0 | H7: =G7+H6 -> 0 | I7: 0 | J7: =I7+J6 -> 0 | K7: 0 | L7: =J7-H7 -> 0 | M7: 0 | N7: =M7/1088 -> 0 | O7: =1088-M7 -> 1088 | P7: =O7/1088 -> 1 | Q7: =E7-$D$5+1 -> 21 | R7: =Q7/1118 -> 0.018783542 | S7: =1118-Q7 -> 1097 | T7: =S7/1118 -> 0.98121646 | W7: ผลงานต่อเดือน | AA7: 0 | AB7: =แผนการก่อสร้าง!M121 -> 0 | AC7: =แผนการก่อสร้าง!N121 -> 0.17176017 | AD7: =แผนการก่อสร้าง!O121 -> 0 | AE7: =แผนการก่อสร้าง!P121 -> 0 | AF7: =แผนการก่อสร้าง!Q121 -> 0 | AG7: =แผนการก่อสร้าง!R121 -> 0 | AH7: =แผนการก่อสร้าง!S121 -> 0 | AI7: =แผนการก่อสร้าง!T121 -> 0 | ... BL7: =แผนการก่อสร้าง!AW121 -> 0
C8: TRUE | D8: =D7+7 -> 45485 | E8: =E7+7 -> 45491 | F8: 4 | G8: 0 | H8: =G8+H7 -> 0 | I8: 0 | J8: =I8+J7 -> 0 | K8: 0 | L8: =J8-H8 -> 0 | M8: =E8-$E$8+1 -> 1 | N8: =M8/1088 -> 0.00091911765 | O8: =1088-M8 -> 1087 | P8: =O8/1088 -> 0.99908088 | Q8: =E8-$D$5+1 -> 28 | R8: =Q8/1118 -> 0.025044723 | S8: =1118-Q8 -> 1090 | T8: =S8/1118 -> 0.97495528 | W8: ผลงานสะสม | AA8: 0 | AB8: =แผนการก่อสร้าง!M123 -> 0 | AC8: =แผนการก่อสร้าง!N123 -> 0.17176017 | AD8: =แผนการก่อสร้าง!O123 -> 0.17176017 | AE8: =แผนการก่อสร้าง!P123 -> 0.17176017 | AF8: =แผนการก่อสร้าง!Q123 -> 0.17176017 | AG8: =แผนการก่อสร้าง!R123 -> 0.17176017 | AH8: =แผนการก่อสร้าง!S123 -> 0.17176017 | AI8: =แผนการก่อสร้าง!T123 -> 0.17176017 | ... BL8: =แผนการก่อสร้าง!AW123 -> 0
C9: TRUE | D9: =D8+7 -> 45492 | E9: =E8+7 -> 45498 | F9: 5 | G9: =7*AB5/AB9 -> 0 | H9: =G9+H8 -> 0 | I9: 0 | J9: =I9+J8 -> 0 | K9: =I9-G9 -> 0 | L9: =J9-H9 -> 0 | M9: =E9-$E$8+1 -> 8 | N9: =M9/1088 -> 0.0073529412 | O9: =1088-M9 -> 1080 | P9: =O9/1088 -> 0.99264706 | Q9: =E9-$D$5+1 -> 35 | R9: =Q9/1118 -> 0.031305903 | S9: =1118-Q9 -> 1083 | T9: =S9/1118 -> 0.9686941 | U9: ผู้รับจ้างเริ่มเข้างาน 18 กรกฎาคม 2567 | X9: จำนวนวัน | Z9: 0 | AA9: 18 | AB9: 13 | AC9: 31 | AD9: 30 | AE9: 31 | AF9: 30 | AG9: 31 | AH9: 31 | AI9: 28 | AJ9: 31 | AK9: 30 | AL9: 31 | AM9: 30 | AN9: 31 | AO9: 31 | AP9: 30 | AQ9: 31 | AR9: 30 | AS9: 31 | AT9: 31 | AU9: 28 | AV9: 31 | AW9: 30 | AX9: 31 | AY9: 30 | AZ9: 31 | BA9: 31 | BB9: 30 | BC9: 31 | BD9: 30 | BE9: 31 | BF9: 31 | BG9: 28 | BH9: 31 | BI9: 30 | BJ9: 31 | BK9: 30 | BL9: 10
C10: TRUE | D10: =D9+7 -> 45499 | E10: =E9+7 -> 45505 | F10: 6 | G10: =(6*AB5/AB9)+(1*AC5/AC9) -> 0 | H10: =G10+H9 -> 0 | I10: 0 | J10: =I10+J9 -> 0 | K10: =I10-G10 -> 0 | L10: =J10-H10 -> 0 | M10: =E10-$E$8+1 -> 15 | N10: =M10/1088 -> 0.013786765 | O10: =1088-M10 -> 1073 | P10: =O10/1088 -> 0.98621324 | Q10: =E10-$D$5+1 -> 42 | R10: =Q10/1118 -> 0.037567084 | S10: =1118-Q10 -> 1076 | T10: =S10/1118 -> 0.96243292
C11: TRUE | D11: 45505 | E11: =D11+6 -> 45511 | F11: 7 | G11: =(E11-D11)*$AC$5/$AC$9 -> 0 | H11: =G11+H10 -> 0 | I11: =((E11-D11+1)*$AC$7/$AC$9) -> 0.038784556 | J11: =I11+J10 -> 0.038784556 | K11: =I11-G11 -> 0.038784556 | L11: =J11-H11 -> 0.038784556 | M11: =E11-$E$8+1 -> 21 | N11: =M11/1088 -> 0.019301471 | O11: =1088-M11 -> 1067 | P11: =O11/1088 -> 0.98069853 | Q11: =E11-$D$5+1 -> 48 | R11: =Q11/1118 -> 0.04293381 | S11: =1118-Q11 -> 1070 | T11: =S11/1118 -> 0.95706619
C12: TRUE | D12: =D11+7 -> 45512 | E12: =D12+7 -> 45519 | F12: 8 | G12: =(E12-D12+1)*$AC$5/$AC$9 -> 0 | H12: =G12+H11 -> 0 | I12: =((E12-D12+1)*$AC$7/$AC$9) -> 0.044325206 | J12: =I12+J11 -> 0.083109762 | K12: =I12-G12 -> 0.044325206 | L12: =J12-H12 -> 0.083109762 | M12: =E12-$E$8+1 -> 29 | N12: =M12/1088 -> 0.026654412 | O12: =1088-M12 -> 1059 | P12: =O12/1088 -> 0.97334559 | Q12: =E12-$D$5+1 -> 56 | R12: =Q12/1118 -> 0.050089445 | S12: =1118-Q12 -> 1062 | T12: =S12/1118 -> 0.94991055
C13: TRUE | D13: =E12+1 -> 45520 | E13: =D13+7 -> 45527 | F13: 9 | G13: =(8)*$AC$5/$AC$9 -> 0 | H13: =G13+H12 -> 0 | I13: =((E13-D13+1)*$AC$7/$AC$9) -> 0.044325206 | J13: =I13+J12 -> 0.12743497 | K13: =I13-G13 -> 0.044325206 | L13: =J13-H13 -> 0.12743497 | M13: =E13-$E$8+1 -> 37 | N13: =M13/1088 -> 0.034007353 | O13: =1088-M13 -> 1051 | P13: =O13/1088 -> 0.96599265 | Q13: =E13-$D$5+1 -> 64 | R13: =Q13/1118 -> 0.057245081 | S13: =1118-Q13 -> 1054 | T13: =S13/1118 -> 0.94275492 | U13: แก้ไขจำนวนวันสะสม +1 วัน ลงวันที่ 16/09/2567
C14: TRUE | D14: =E13+1 -> 45528 | E14: =D14+7 -> 45535 | F14: 10 | G14: =(8)*$AC$5/$AC$9 -> 0 | H14: =G14+H13 -> 0 | I14: =((E14-D14+1)*$AC$7/$AC$9) -> 0.044325206 | J14: =I14+J13 -> 0.17176017 | K14: =I14-G14 -> 0.044325206 | L14: =J14-H14 -> 0.17176017 | M14: =E14-$E$8+1 -> 45 | N14: =M14/1088 -> 0.041360294 | O14: =1088-M14 -> 1043 | P14: =O14/1088 -> 0.95863971 | Q14: =E14-$D$5+1 -> 72 | R14: =Q14/1118 -> 0.064400716 | S14: =1118-Q14 -> 1046 | T14: =S14/1118 -> 0.93559928 | U14: ผลงานสัปดาห์ที่ 10 24-31 สิงหาคม ผลงานที่ 0.155
C15: TRUE | D15: 45536 | E15: =D15+6 -> 45542 | F15: 11 | G15: =(7*AD5/AD9) -> 0 | H15: =G15+H14 -> 0 | I15: =(7*AD7/AD9) -> 0 | J15: =I15+J14 -> 0.17176017 | K15: =I15-G15 -> 0 | L15: =J15-H15 -> 0.17176017 | M15: =E15-$E$8+1 -> 52 | N15: =M15/1088 -> 0.047794118 | O15: =1088-M15 -> 1036 | P15: =O15/1088 -> 0.95220588 | Q15: =E15-$D$5+1 -> 79 | R15: =Q15/1118 -> 0.070661896 | S15: =1118-Q15 -> 1039 | T15: =S15/1118 -> 0.9293381 | U15: ผลงานเดือนสิงหาคมวันที่ 31
C16: TRUE | D16: =D15+7 -> 45543 | E16: =E15+8 -> 45550 | F16: 12 | G16: =(8*AD5/AD9) -> 0 | H16: =G16+H15 -> 0 | I16: =(8*AD7/AD9) -> 0 | J16: =I16+J15 -> 0.17176017 | K16: =I16-G16 -> 0 | L16: =J16-H16 -> 0.17176017 | M16: =E16-$E$8+1 -> 60 | N16: =M16/1088 -> 0.055147059 | O16: =1088-M16 -> 1028 | P16: =O16/1088 -> 0.94485294 | Q16: =E16-$D$5+1 -> 87 | R16: =Q16/1118 -> 0.077817531 | S16: =1118-Q16 -> 1031 | T16: =S16/1118 -> 0.92218247 | U16: จะไม่ตรงกับสัปดาห์ของสิงหา | X16: ตารางคำนวณ แผน - ผลงาน เพื่อประชุม weekly
C17: TRUE | D17: =D16+8 -> 45551 | E17: =E16+8 -> 45558 | F17: 13 | G17: =(8*AD5/AD9) -> 0 | H17: =G17+H16 -> 0 | I17: =(8*AD7/AD9) -> 0 | J17: =I17+J16 -> 0.17176017 | K17: =I17-G17 -> 0 | L17: =J17-H17 -> 0.17176017 | M17: =E17-$E$8+1 -> 68 | N17: =M17/1088 -> 0.0625 | O17: =1088-M17 -> 1020 | P17: =O17/1088 -> 0.9375 | Q17: =E17-$D$5+1 -> 95 | R17: =Q17/1118 -> 0.084973166 | S17: =1118-Q17 -> 1023 | T17: =S17/1118 -> 0.91502683 | U17: เนื่องจากรายงานประจำเดือนมีการ | X17: จากวันที่ | Y17: ถึงวันที่ | Z17: แผนงาน % | AA17: %แผนงานสะสม | AB17: ผลงาน% | AC17: ผลงานสะสม% | AD17: ช้าเร็วกว่าแผนงาน | AE17: เร็วช้ากว่าแผนสะสม | AF17: จำนวนวันสะสม | AG17: ระยะเวลาดำเนินการ % | AH17: ระยะเวลาดำเนินการควบคุมงาน | AI17: ระยะเวลาดำเนินการควบคุมงาน % | AJ17: เวลาคงเหลือก่อสร้าง | AK17: เวลาคงเหลือ %
C18: TRUE | D18: =D17+8 -> 45559 | E18: =E17+7 -> 45565 | F18: 14 | G18: =(7*AD5/AD9) -> 0 | H18: =G18+H17 -> 0 | I18: =(7*AD7/AD9) -> 0 | J18: =I18+J17 -> 0.17176017 | K18: =I18-G18 -> 0 | L18: =J18-H18 -> 0.17176017 | M18: =E18-$E$8+1 -> 75 | N18: =M18/1088 -> 0.068933824 | O18: =1088-M18 -> 1013 | P18: =O18/1088 -> 0.93106618 | Q18: =E18-$D$5+1 -> 102 | R18: =Q18/1118 -> 0.091234347 | S18: =1118-Q18 -> 1016 | T18: =S18/1118 -> 0.90876565 | U18: ปรับให้เริ่มวันที่ 1-7,8-15,16-23,24-31 ตลอด | X18: =D20+8 -> 45581 | Y18: =E20+13 -> 45593 | Z18: =(Y18-D21+1)*$AE$5/$AE$9 -> 0 | AA18: =Z18+H20 -> 0 | AB18: =(Y18-X18+1)*$AE$7/$AE$9 -> 0 | AC18: =AB18+J20 -> 0.17176017 | AD18: =AB18-Z18 -> 0 | AE18: =AC18-AA18 -> 0.17176017 | AF18: =Y18-$E$8+1 -> 103 | AG18: =AF18/840 -> 0.12261905 | AH18: =Y18-$D$5+1 -> 130 | AI18: =AH18/870 -> 0.14942529 | AJ18: =870-AH18 -> 740 | AK18: =AJ18/870 -> 0.85057471
C19: TRUE | D19: =D18+7 -> 45566 | E19: =E18+7 -> 45572 | F19: 15 | G19: =(E19-D19+1)*$AE$5/$AE$9 -> 0 | H19: =G19+H18 -> 0 | I19: =(E19-D19+1)*$AE$7/$AE$9 -> 0 | J19: =I19+J18 -> 0.17176017 | K19: =I19-G19 -> 0 | L19: =J19-H19 -> 0.17176017 | M19: =E19-$E$8+1 -> 82 | N19: =M19/1088 -> 0.075367647 | O19: =1088-M19 -> 1006 | P19: =O19/1088 -> 0.92463235 | Q19: =E19-$D$5+1 -> 109 | R19: =Q19/1118 -> 0.097495528 | S19: =1118-Q19 -> 1009 | T19: =S19/1118 -> 0.90250447
C20: TRUE | D20: =D19+7 -> 45573 | E20: =E19+8 -> 45580 | F20: 16 | G20: =(E20-D20+1)*$AE$5/$AE$9 -> 0 | H20: =G20+H19 -> 0 | I20: =(E20-D20+1)*$AE$7/$AE$9 -> 0 | J20: =I20+J19 -> 0.17176017 | K20: =I20-G20 -> 0 | L20: =J20-H20 -> 0.17176017 | M20: =E20-$E$8+1 -> 90 | N20: =M20/1088 -> 0.082720588 | O20: =1088-M20 -> 998 | P20: =O20/1088 -> 0.91727941 | Q20: =E20-$D$5+1 -> 117 | R20: =Q20/1118 -> 0.10465116 | S20: =1118-Q20 -> 1001 | T20: =S20/1118 -> 0.89534884 | U20: ขยายระเวลาก่อสร้างออกไป 248 วัน
C21: TRUE | D21: =D20+8 -> 45581 | E21: =E20+8 -> 45588 | F21: 17 | G21: =(E21-D21+1)*$AE$5/$AE$9 -> 0 | H21: =G21+H20 -> 0 | I21: =(E21-D21+1)*$AE$7/$AE$9 -> 0 | J21: =I21+J20 -> 0.17176017 | K21: =I21-G21 -> 0 | L21: =J21-H21 -> 0.17176017 | M21: =E21-$E$8+1 -> 98 | N21: =M21/1088 -> 0.090073529 | O21: =1088-M21 -> 990 | P21: =O21/1088 -> 0.90992647 | Q21: =E21-$D$5+1 -> 125 | R21: =Q21/1118 -> 0.1118068 | S21: =1118-Q21 -> 993 | T21: =S21/1118 -> 0.8881932 | U21: ดังนั้นจึงขยายระยะเวลาควบคุมงานออกไป 248 วัน
C22: TRUE | D22: =D21+8 -> 45589 | E22: =E21+8 -> 45596 | F22: 18 | G22: =(E22-D22+1)*$AE$5/$AE$9 -> 0 | H22: =G22+H21 -> 0 | I22: =(E22-D22+1)*$AE$7/$AE$9 -> 0 | J22: =I22+J21 -> 0.17176017 | K22: =I22-G22 -> 0 | L22: =J22-H22 -> 0.17176017 | M22: =E22-$E$8+1 -> 106 | N22: =M22/1088 -> 0.097426471 | O22: =1088-M22 -> 982 | P22: =O22/1088 -> 0.90257353 | Q22: =E22-$D$5+1 -> 133 | R22: =Q22/1118 -> 0.11896243 | S22: =1118-Q22 -> 985 | T22: =S22/1118 -> 0.88103757
C23: TRUE | D23: =D22+8 -> 45597 | E23: =E22+7 -> 45603 | F23: 19 | G23: =(E23-D23+1)*$AF$5/$AF$9 -> 0 | H23: =G23+H22 -> 0 | I23: =(E23-D23+1)*$AF$7/$AF$9 -> 0 | J23: =I23+J22 -> 0.17176017 | K23: =I23-G23 -> 0 | L23: =J23-H23 -> 0.17176017 | M23: =E23-$E$8+1 -> 113 | N23: =M23/1088 -> 0.10386029 | O23: =1088-M23 -> 975 | P23: =O23/1088 -> 0.89613971 | Q23: =E23-$D$5+1 -> 140 | R23: =Q23/1118 -> 0.12522361 | S23: =1118-Q23 -> 978 | T23: =S23/1118 -> 0.87477639
C24: TRUE | D24: =D23+7 -> 45604 | E24: =E23+8 -> 45611 | F24: 20 | G24: =(E24-D24+1)*$AF$5/$AF$9 -> 0 | H24: =G24+H23 -> 0 | I24: =(E24-D24+1)*$AF$7/$AF$9 -> 0 | J24: =I24+J23 -> 0.17176017 | K24: =I24-G24 -> 0 | L24: =J24-H24 -> 0.17176017 | M24: =E24-$E$8+1 -> 121 | N24: =M24/1088 -> 0.11121324 | O24: =1088-M24 -> 967 | P24: =O24/1088 -> 0.88878676 | Q24: =E24-$D$5+1 -> 148 | R24: =Q24/1118 -> 0.13237925 | S24: =1118-Q24 -> 970 | T24: =S24/1118 -> 0.86762075 | AE24: ระยะเวลาก่อสร้างคงเหลือ | AF24: =840-AF18 -> 737
C25: TRUE | D25: =D24+8 -> 45612 | E25: =E24+8 -> 45619 | F25: 21 | G25: =(E25-D25+1)*$AF$5/$AF$9 -> 0 | H25: =G25+H24 -> 0 | I25: =(E25-D25+1)*$AF$7/$AF$9 -> 0 | J25: =I25+J24 -> 0.17176017 | K25: =I25-G25 -> 0 | L25: =J25-H25 -> 0.17176017 | M25: =E25-$E$8+1 -> 129 | N25: =M25/1088 -> 0.11856618 | O25: =1088-M25 -> 959 | P25: =O25/1088 -> 0.88143382 | Q25: =E25-$D$5+1 -> 156 | R25: =Q25/1118 -> 0.13953488 | S25: =1118-Q25 -> 962 | T25: =S25/1118 -> 0.86046512
C26: TRUE | D26: =D25+8 -> 45620 | E26: =E25+7 -> 45626 | F26: 22 | G26: =(E26-D26+1)*$AF$5/$AF$9 -> 0 | H26: =G26+H25 -> 0 | I26: =(E26-D26+1)*$AF$7/$AF$9 -> 0 | J26: =I26+J25 -> 0.17176017 | K26: =I26-G26 -> 0 | L26: =J26-H26 -> 0.17176017 | M26: =E26-$E$8+1 -> 136 | N26: =M26/1088 -> 0.125 | O26: =1088-M26 -> 952 | P26: =O26/1088 -> 0.875 | Q26: =E26-$D$5+1 -> 163 | R26: =Q26/1118 -> 0.14579606 | S26: =1118-Q26 -> 955 | T26: =S26/1118 -> 0.85420394
C27: TRUE | D27: =D26+7 -> 45627 | E27: =E26+7 -> 45633 | F27: 23 | G27: =(E27-D27+1)*$AG$5/$AG$9 -> 0 | H27: =G27+H26 -> 0 | I27: =(E27-D27+1)*$AG$7/$AG$9 -> 0 | J27: =I27+J26 -> 0.17176017 | K27: =I27-G27 -> 0 | L27: =J27-H27 -> 0.17176017 | M27: =E27-$E$8+1 -> 143 | N27: =M27/1088 -> 0.13143382 | O27: =1088-M27 -> 945 | P27: =O27/1088 -> 0.86856618 | Q27: =E27-$D$5+1 -> 170 | R27: =Q27/1118 -> 0.15205725 | S27: =1118-Q27 -> 948 | T27: =S27/1118 -> 0.84794275
C28: TRUE | D28: =D27+7 -> 45634 | E28: =E27+8 -> 45641 | F28: 24 | G28: =(E28-D28+1)*$AG$5/$AG$9 -> 0 | H28: =G28+H27 -> 0 | I28: =(E28-D28+1)*$AG$7/$AG$9 -> 0 | J28: =I28+J27 -> 0.17176017 | K28: =I28-G28 -> 0 | L28: =J28-H28 -> 0.17176017 | M28: =E28-$E$8+1 -> 151 | N28: =M28/1088 -> 0.13878676 | O28: =1088-M28 -> 937 | P28: =O28/1088 -> 0.86121324 | Q28: =E28-$D$5+1 -> 178 | R28: =Q28/1118 -> 0.15921288 | S28: =1118-Q28 -> 940 | T28: =S28/1118 -> 0.84078712
C29: TRUE | D29: =D28+8 -> 45642 | E29: =E28+8 -> 45649 | F29: 25 | G29: =(E29-D29+1)*$AG$5/$AG$9 -> 0 | H29: =G29+H28 -> 0 | I29: =(E29-D29+1)*$AG$7/$AG$9 -> 0 | J29: =I29+J28 -> 0.17176017 | K29: =I29-G29 -> 0 | L29: =J29-H29 -> 0.17176017 | M29: =E29-$E$8+1 -> 159 | N29: =M29/1088 -> 0.14613971 | O29: =1088-M29 -> 929 | P29: =O29/1088 -> 0.85386029 | Q29: =E29-$D$5+1 -> 186 | R29: =Q29/1118 -> 0.16636852 | S29: =1118-Q29 -> 932 | T29: =S29/1118 -> 0.83363148
C30: TRUE | D30: =D29+8 -> 45650 | E30: =E29+8 -> 45657 | F30: 26 | G30: =(E30-D30+1)*$AG$5/$AG$9 -> 0 | H30: =G30+H29 -> 0 | I30: =(E30-D30+1)*$AG$7/$AG$9 -> 0 | J30: =I30+J29 -> 0.17176017 | K30: =I30-G30 -> 0 | L30: =J30-H30 -> 0.17176017 | M30: =E30-$E$8+1 -> 167 | N30: =M30/1088 -> 0.15349265 | O30: =1088-M30 -> 921 | P30: =O30/1088 -> 0.84650735 | Q30: =E30-$D$5+1 -> 194 | R30: =Q30/1118 -> 0.17352415 | S30: =1118-Q30 -> 924 | T30: =S30/1118 -> 0.82647585
C31: TRUE | D31: =D30+8 -> 45658 | E31: =E30+7 -> 45664 | F31: 27 | G31: =(E31-D31+1)*$AH$5/$AH$9 -> 0 | H31: =G31+H30 -> 0 | I31: =(E31-D31+1)*$AH$7/$AH$9 -> 0 | J31: =I31+J30 -> 0.17176017 | K31: =I31-G31 -> 0 | L31: =J31-H31 -> 0.17176017 | M31: =E31-$E$8+1 -> 174 | N31: =M31/1088 -> 0.15992647 | O31: =1088-M31 -> 914 | P31: =O31/1088 -> 0.84007353 | Q31: =E31-$D$5+1 -> 201 | R31: =Q31/1118 -> 0.17978533 | S31: =1118-Q31 -> 917 | T31: =S31/1118 -> 0.82021467
C32: TRUE | D32: =D31+7 -> 45665 | E32: =E31+8 -> 45672 | F32: 28 | G32: =(E32-D32+1)*$AH$5/$AH$9 -> 0 | H32: =G32+H31 -> 0 | I32: =(E32-D32+1)*$AH$7/$AH$9 -> 0 | J32: =I32+J31 -> 0.17176017 | K32: =I32-G32 -> 0 | L32: =J32-H32 -> 0.17176017 | M32: =E32-$E$8+1 -> 182 | N32: =M32/1088 -> 0.16727941 | O32: =1088-M32 -> 906 | P32: =O32/1088 -> 0.83272059 | Q32: =E32-$D$5+1 -> 209 | R32: =Q32/1118 -> 0.18694097 | S32: =1118-Q32 -> 909 | T32: =S32/1118 -> 0.81305903
C33: TRUE | D33: =D32+8 -> 45673 | E33: =E32+8 -> 45680 | F33: 29 | G33: =(E33-D33+1)*$AH$5/$AH$9 -> 0 | H33: =G33+H32 -> 0 | I33: =(E33-D33+1)*$AH$7/$AH$9 -> 0 | J33: =I33+J32 -> 0.17176017 | K33: =I33-G33 -> 0 | L33: =J33-H33 -> 0.17176017 | M33: =E33-$E$8+1 -> 190 | N33: =M33/1088 -> 0.17463235 | O33: =1088-M33 -> 898 | P33: =O33/1088 -> 0.82536765 | Q33: =E33-$D$5+1 -> 217 | R33: =Q33/1118 -> 0.1940966 | S33: =1118-Q33 -> 901 | T33: =S33/1118 -> 0.8059034
C34: TRUE | D34: =D33+8 -> 45681 | E34: =E33+8 -> 45688 | F34: 30 | G34: =(E34-D34+1)*$AH$5/$AH$9 -> 0 | H34: =G34+H33 -> 0 | I34: =(E34-D34+1)*$AH$7/$AH$9 -> 0 | J34: =I34+J33 -> 0.17176017 | K34: =I34-G34 -> 0 | L34: =J34-H34 -> 0.17176017 | M34: =E34-$E$8+1 -> 198 | N34: =M34/1088 -> 0.18198529 | O34: =1088-M34 -> 890 | P34: =O34/1088 -> 0.81801471 | Q34: =E34-$D$5+1 -> 225 | R34: =Q34/1118 -> 0.20125224 | S34: =1118-Q34 -> 893 | T34: =S34/1118 -> 0.79874776
C35: TRUE | D35: =D34+8 -> 45689 | E35: =E34+7 -> 45695 | F35: 31 | G35: =(E35-D35+1)*$AI$5/$AI$9 -> 0 | H35: =G35+H34 -> 0 | I35: =(E35-D35+1)*$AI$7/$AI$9 -> 0 | J35: =I35+J34 -> 0.17176017 | K35: =I35-G35 -> 0 | L35: =J35-H35 -> 0.17176017 | M35: =E35-$E$8+1 -> 205 | N35: =M35/1088 -> 0.18841912 | O35: =1088-M35 -> 883 | P35: =O35/1088 -> 0.81158088 | Q35: =E35-$D$5+1 -> 232 | R35: =Q35/1118 -> 0.20751342 | S35: =1118-Q35 -> 886 | T35: =S35/1118 -> 0.79248658
C36: TRUE | D36: =D35+7 -> 45696 | E36: =E35+8 -> 45703 | F36: 32 | G36: =(E36-D36+1)*$AI$5/$AI$9 -> 0 | H36: =G36+H35 -> 0 | I36: =(E36-D36+1)*$AI$7/$AI$9 -> 0 | J36: =I36+J35 -> 0.17176017 | K36: =I36-G36 -> 0 | L36: =J36-H36 -> 0.17176017 | M36: =E36-$E$8+1 -> 213 | N36: =M36/1088 -> 0.19577206 | O36: =1088-M36 -> 875 | P36: =O36/1088 -> 0.80422794 | Q36: =E36-$D$5+1 -> 240 | R36: =Q36/1118 -> 0.21466905 | S36: =1118-Q36 -> 878 | T36: =S36/1118 -> 0.78533095
C37: TRUE | D37: =D36+8 -> 45704 | E37: =E36+8 -> 45711 | F37: 33 | G37: =(E37-D37+1)*$AI$5/$AI$9 -> 0 | H37: =G37+H36 -> 0 | I37: =(E37-D37+1)*$AI$7/$AI$9 -> 0 | J37: =I37+J36 -> 0.17176017 | K37: =I37-G37 -> 0 | L37: =J37-H37 -> 0.17176017 | M37: =E37-$E$8+1 -> 221 | N37: =M37/1088 -> 0.203125 | O37: =1088-M37 -> 867 | P37: =O37/1088 -> 0.796875 | Q37: =E37-$D$5+1 -> 248 | R37: =Q37/1118 -> 0.22182469 | S37: =1118-Q37 -> 870 | T37: =S37/1118 -> 0.77817531
C38: TRUE | D38: =D37+8 -> 45712 | E38: =E37+5 -> 45716 | F38: 34 | G38: =(E38-D38+1)*$AI$5/$AI$9 -> 0 | H38: =G38+H37 -> 0 | I38: =(E38-D38+1)*$AI$7/$AI$9 -> 0 | J38: =I38+J37 -> 0.17176017 | K38: =I38-G38 -> 0 | L38: =J38-H38 -> 0.17176017 | M38: =E38-$E$8+1 -> 226 | N38: =M38/1088 -> 0.20772059 | O38: =1088-M38 -> 862 | P38: =O38/1088 -> 0.79227941 | Q38: =E38-$D$5+1 -> 253 | R38: =Q38/1118 -> 0.22629696 | S38: =1118-Q38 -> 865 | T38: =S38/1118 -> 0.77370304
C39: TRUE | D39: =D38+5 -> 45717 | E39: =E38+7 -> 45723 | F39: 35 | G39: =(E39-D39+1)*$AJ$5/$AJ$9 -> 0 | H39: =G39+H38 -> 0 | I39: =(E39-D39+1)*$AJ$7/$AJ$9 -> 0 | J39: =I39+J38 -> 0.17176017 | K39: =I39-G39 -> 0 | L39: =J39-H39 -> 0.17176017 | M39: =E39-$E$8+1 -> 233 | N39: =M39/1088 -> 0.21415441 | O39: =1088-M39 -> 855 | P39: =O39/1088 -> 0.78584559 | Q39: =E39-$D$5+1 -> 260 | R39: =Q39/1118 -> 0.23255814 | S39: =1118-Q39 -> 858 | T39: =S39/1118 -> 0.76744186
C40: TRUE | D40: =D39+7 -> 45724 | E40: =E39+8 -> 45731 | F40: 36 | G40: =(E40-D40+1)*$AJ$5/$AJ$9 -> 0 | H40: =G40+H39 -> 0 | I40: =(E40-D40+1)*$AJ$7/$AJ$9 -> 0 | J40: =I40+J39 -> 0.17176017 | K40: =I40-G40 -> 0 | L40: =J40-H40 -> 0.17176017 | M40: =E40-$E$8+1 -> 241 | N40: =M40/1088 -> 0.22150735 | O40: =1088-M40 -> 847 | P40: =O40/1088 -> 0.77849265 | Q40: =E40-$D$5+1 -> 268 | R40: =Q40/1118 -> 0.23971377 | S40: =1118-Q40 -> 850 | T40: =S40/1118 -> 0.76028623
...

Sheet ผลweekly
B3: ที่ | C3: งานที่ดำเนินการ | D3: สัดส่วนของงาน (%) | E3: ผลงาน % | G3: หมายเหตุ
E4: สะสมสัปดาห์ก่อน | F4: สะสมสัปดาห์นี้
B5: 1 | C5: งานเขื่อนป้องกันตลิ่ง
B6: 1.1 | C6: งานเขื่อนป้องกันตลิ่ง แบบที่ 1 | D6: 2.134 | E6: ='ผลงานรายสัปดาห์(%)'!L7*D6/100 -> 0.15401586 | F6: ='ผลงานรายสัปดาห์(%)'!M7*D6/100 -> 0.15401586
B7: (1) | C7: งานคาน | D7: 0.902 | E7: ='ผลงานรายสัปดาห์(%)'!L9*D7/100 -> 0 | F7: ='ผลงานรายสัปดาห์(%)'!M9*D7/100 -> 0
B8: (2) | C8: งานกำแพง w15 + บันได | D8: 0.38 | E8: ='ผลงานรายสัปดาห์(%)'!L11*D8/100 -> 0 | F8: ='ผลงานรายสัปดาห์(%)'!M11*D8/100 -> 0
B9: (3) | C9: งานราวกันตก | D9: 0.575 | E9: ='ผลงานรายสัปดาห์(%)'!L13*D9/100 -> 0 | F9: ='ผลงานรายสัปดาห์(%)'!M13*D9/100 -> 0
B10: (4) | C10: งานวัสดุปูพื้น | D10: 0.331 | E10: ='ผลงานรายสัปดาห์(%)'!L15*D10/100 -> 0 | F10: ='ผลงานรายสัปดาห์(%)'!M15*D10/100 -> 0
B11: 1.2 | C11: งานเขื่อนป้องกันตลิ่ง แบบที่ 2 | D11: 2.098 | E11: ='ผลงานรายสัปดาห์(%)'!L17*D11/100 -> 0.0072919553 | F11: ='ผลงานรายสัปดาห์(%)'!M17*D11/100 -> 0.0072919553
B12: (1) | C12: งานคาน | D12: 0.476 | E12: ='ผลงานรายสัปดาห์(%)'!L19*D12/100 -> 0 | F12: ='ผลงานรายสัปดาห์(%)'!M19*D12/100 -> 0
B13: (2) | C13: งานบันได | D13: 0.222 | E13: ='ผลงานรายสัปดาห์(%)'!L21*D13/100 -> 0 | F13: ='ผลงานรายสัปดาห์(%)'!M21*D13/100 -> 0
B14: (3) | C14: งานราวกันตก | D14: 0.067 | E14: ='ผลงานรายสัปดาห์(%)'!L23*D14/100 -> 0 | F14: ='ผลงานรายสัปดาห์(%)'!M23*D14/100 -> 0
B15: 1.3 | C15: งานเขื่อนป้องกันตลิ่ง แบบที่ 1 | D15: 1.79 | E15: ='ผลงานรายสัปดาห์(%)'!L25*D15/100 -> 1.1600984 | F15: ='ผลงานรายสัปดาห์(%)'!M25*D15/100 -> 1.1600984
B16: (1) | C16: งานคาน | D16: 0.877 | E16: ='ผลงานรายสัปดาห์(%)'!L27*D16/100 -> 0 | F16: ='ผลงานรายสัปดาห์(%)'!M27*D16/100 -> 0
B17: (2) | C17: งานบันได | D17: 0.37 | E17: ='ผลงานรายสัปดาห์(%)'!L29*D17/100 -> 0 | F17: ='ผลงานรายสัปดาห์(%)'!M29*D17/100 -> 0
B18: (3) | C18: งานราวกันตก | D18: 0.564 | E18: ='ผลงานรายสัปดาห์(%)'!L31*D18/100 -> 0 | F18: ='ผลงานรายสัปดาห์(%)'!M31*D18/100 -> 0
B19: (4) | C19: งานวัสดุปูพื้น | D19: 0.439 | E19: ='ผลงานรายสัปดาห์(%)'!L33*D19/100 -> 0 | F19: ='ผลงานรายสัปดาห์(%)'!M33*D19/100 -> 0
B20: 1.4 | C20: งานเขื่อนป้องกันตลิ่ง แบบที่ 4 ช่วงที่ 1 | D20: 1.185 | E20: ='ผลงานรายสัปดาห์(%)'!L35*D20/100 -> 0.63598537 | F20: ='ผลงานรายสัปดาห์(%)'!M35*D20/100 -> 0.63598537
B21: (1) | C21: งานคาน | D21: 0.133 | E21: ='ผลงานรายสัปดาห์(%)'!L37*D21/100 -> 0 | F21: ='ผลงานรายสัปดาห์(%)'!M37*D21/100 -> 0
B22: (2) | C22: งานราวกันตก และ งานระบายน้ำหลังเขื่อน | D22: 0.11 | E22: ='ผลงานรายสัปดาห์(%)'!L39*D22/100 -> 0 | F22: ='ผลงานรายสัปดาห์(%)'!M39*D22/100 -> 0
B23: 1.5 | C23: งานเขื่อนป้องกันตลิ่ง แบบที่ 4 ช่วงที่ 2 | D23: 1.332 | E23: ='ผลงานรายสัปดาห์(%)'!L41*D23/100 -> 0.72448767 | F23: ='ผลงานรายสัปดาห์(%)'!M41*D23/100 -> 0.72448767
B24: (1) | C24: งานคาน | D24: 0.15 | E24: ='ผลงานรายสัปดาห์(%)'!L43*D24/100 -> 0 | F24: ='ผลงานรายสัปดาห์(%)'!M43*D24/100 -> 0
B25: (2) | C25: งานราวกันตก และ งานระบายน้ำหลังเขื่อน | D25: 0.124 | E25: ='ผลงานรายสัปดาห์(%)'!L45*D25/100 -> 0 | F25: ='ผลงานรายสัปดาห์(%)'!M45*D25/100 -> 0
B26: 1.6 | C26: งานเขื่อนป้องกันตลิ่ง แบบที่ 5 | D26: 1.393 | E26: ='ผลงานรายสัปดาห์(%)'!L47*D26/100 -> 1.1474849 | F26: ='ผลงานรายสัปดาห์(%)'!M47*D26/100 -> 1.1474849
B27: (1) | C27: งานคาน | D27: 0.15 | E27: ='ผลงานรายสัปดาห์(%)'!L49*D27/100 -> 0 | F27: ='ผลงานรายสัปดาห์(%)'!M49*D27/100 -> 0
B28: (2) | C28: งานราวกันตก และ งานระบายน้ำหลังเขื่อน | D28: 0.124 | E28: ='ผลงานรายสัปดาห์(%)'!L51*D28/100 -> 0 | F28: ='ผลงานรายสัปดาห์(%)'!M51*D28/100 -> 0
B29: 1.7 | C29: งานเขื่อนป้องกันตลิ่ง แบบที่ 5 (มีผิวจราจรด้านหลังเขื่อน) | D29: 6.105 | E29: ='ผลงานรายสัปดาห์(%)'!L53*D29/100 -> 2.6226942 | F29: ='ผลงานรายสัปดาห์(%)'!M53*D29/100 -> 2.6226942
B30: (1) | C30: งานคาน | D30: 0.679 | E30: ='ผลงานรายสัปดาห์(%)'!L55*D30/100 -> 0 | F30: ='ผลงานรายสัปดาห์(%)'!M55*D30/100 -> 0
B31: (2) | C31: งานราวกันตก และ งานระบายน้ำหลังเขื่อน | D31: 0.562 | E31: ='ผลงานรายสัปดาห์(%)'!L57*D31/100 -> 0 | F31: ='ผลงานรายสัปดาห์(%)'!M57*D31/100 -> 0
B32: 1.8 | C32: งานเขื่อนป้องกันตลิ่ง แบบที่ 5 ช่วง | D32: 6.781 | E32: ='ผลงานรายสัปดาห์(%)'!L59*D32/100 -> 1.3520873 | F32: ='ผลงานรายสัปดาห์(%)'!M59*D32/100 -> 1.3520873
B33: (1) | C33: งานคาน | D33: 0.767 | E33: ='ผลงานรายสัปดาห์(%)'!L61*D33/100 -> 0 | F33: ='ผลงานรายสัปดาห์(%)'!M61*D33/100 -> 0
B34: (2) | C34: งานราวกันตก และ งานระบายน้ำหลังเขื่อน | D34: 0.897 | E34: ='ผลงานรายสัปดาห์(%)'!L63*D34/100 -> 0 | F34: ='ผลงานรายสัปดาห์(%)'!M63*D34/100 -> 0
B35: 1.9 | C35: งานเขื่อนป้องกันตลิ่ง แบบที่ 6 ช่วงที่ 1 | D35: 0.144 | E35: ='ผลงานรายสัปดาห์(%)'!L65*D35/100 -> 0 | F35: ='ผลงานรายสัปดาห์(%)'!M65*D35/100 -> 0
B36: 1.10 | C36: งานเขื่อนป้องกันตลิ่ง แบบที่ 6 ช่วงที่ 2 | D36: 0.672 | E36: ='ผลงานรายสัปดาห์(%)'!L67*D36/100 -> 0 | F36: ='ผลงานรายสัปดาห์(%)'!M67*D36/100 -> 0
B37: 1.11 | C37: งานเขื่อนป้องกันตลิ่ง แบบที่ 6 ช่วงที่ 3 | D37: 0.14 | E37: ='ผลงานรายสัปดาห์(%)'!L69*D37/100 -> 0 | F37: ='ผลงานรายสัปดาห์(%)'!M69*D37/100 -> 0
B38: 1.12 | C38: งานเขื่อนป้องกันตลิ่ง แบบที่ 7 | D38: 0.67 | E38: ='ผลงานรายสัปดาห์(%)'!L71*D38/100 -> 0 | F38: ='ผลงานรายสัปดาห์(%)'!M71*D38/100 -> 0
B39: 2 | C39: งานปรับปรุงภูมิทัศน์
B40: 2.1 | C40: งานปรับปรุงภูมิทัศน์บริเวณลานทางเข้าเทศบาลฯ | D40: 1.383 | E40: ='ผลงานรายสัปดาห์(%)'!L75*D40/100 -> 0 | F40: ='ผลงานรายสัปดาห์(%)'!M75*D40/100 -> 0
B41: 2.2 | C41: งานปรับปรุงทางปั่นจักรยาน ริมเขื่อนป้องกันตลิ่งฯ | D41: 9.531 | E41: ='ผลงานรายสัปดาห์(%)'!L77*D41/100 -> 0.014978458 | F41: ='ผลงานรายสัปดาห์(%)'!M77*D41/100 -> 0.014978458
B42: 3 | C42: งานทาง
...

Sheet แผนการก่อสร้าง
A7: ลำดับ | B7: รายการ | C7: หน่วย | D7: ปริมาณ | E7: แผนงาน | F7: % | G7: ผลงาน | H7: % | I7: ราคาต่อหน่วย | J7: จำนวนเงิน | K7: % | L7: พ.ศ. 2567 | S7: พ.ศ. 2568 | AE7: พ.ศ. 2569 | AQ7: พ.ศ. 2570 | BM7: พ.ศ. 2567 | BT7: พ.ศ. 2568 | CF7: พ.ศ. 2569 | CR7: พ.ศ. 2570 | DB7: Sum%
A8: ที่ | I8: (บาท) | J8: (บาท) | L8: ก.ค. | N8: ส.ค. | O8: ก.ย. | P8: ต.ค. | Q8: พ.ย. | R8: ธ.ค. | S8: ม.ค. | T8: ก.พ. | U8: มี.ค. | V8: เม.ย. | W8: พ.ค. | X8: มิ.ย. | Y8: ก.ค. | Z8: ส.ค. | AA8: ก.ย. | AB8: ต.ค. | AC8: พ.ย. | AD8: ธ.ค. | AE8: ม.ค. | AF8: ก.พ. | AG8: มี.ค. | AH8: เม.ย. | AI8: พ.ค. | AJ8: มิ.ย. | AK8: ก.ค | AL8: ส.ค | AM8: ก.ย | AN8: ต.ค | AO8: พ.ย | AP8: ธ.ค. | AQ8: ม.ค. | AR8: ก.พ. | AS8: มี.ค. | AT8: เม.ย. | AU8: พ.ค. | AV8: มิ.ย. | AW8: ก.ค. | BM8: ก.ค. | BO8: ส.ค. | BP8: ก.ย. | BQ8: ต.ค. | BR8: พ.ย. | BS8: ธ.ค. | BT8: ม.ค. | BU8: ก.พ. | BV8: มี.ค. | BW8: เม.ย. | BX8: พ.ค. | BY8: มิ.ย. | BZ8: ก.ค. | CA8: ส.ค. | CB8: ก.ย. | CC8: ต.ค. | CD8: พ.ย. | CE8: ธ.ค. | CF8: ม.ค. | CG8: ก.พ. | CH8: มี.ค. | CI8: เม.ย. | CJ8: พ.ค. | CK8: มิ.ย. | CL8: ก.ค | CM8: ส.ค | CN8: ก.ย | CO8: ต.ค | CP8: พ.ย. | CQ8: ธ.ค. | CR8: ม.ค. | CS8: ก.พ. | CT8: มี.ค. | CU8: เม.ย. | CV8: พ.ค. | CW8: มิ.ย. | CX8: ก.ค
A9: 1 | B9: งานเขื่อนป้องกันตลิ่ง | AZ9: 100
A11: 1.1 | B11: งานเขื่อนป้องกันตลิ่ง แบบที่ 1 | C11: เหมาจ่าย | D11: 1 | E11: =F11*100/SUM(K11:K20) -> 29.622732 | F11: =K11*SUM(M11:AG11)/100 -> 1.2806566 | G11: =D11*H11/100 -> 0.07212 | H11: =SUM(L12:AJ12) -> 7.212 | I11: ='BOQ แก้ไขสัญญา'!AF10 -> 5090507 | J11: =D11*I11 -> 5090507 | K11: =J11*100/GTotal -> 2.1344276 | AA11: 5 | AB11: 5 | AC11: 10 | AD11: 10 | AE11: 10 | AF11: 10 | AG11: 10 | AH11: 10 | AI11: 10 | AJ11: 10 | AK11: 10 | BL11: 1 | BN11: =M11*$K11/100 -> 0 | BO11: =N11*$K11/100 -> 0 | BP11: =O11*$K11/100 -> 0 | BQ11: =P11*$K11/100 -> 0 | BR11: =Q11*$K11/100 -> 0 | BS11: =R11*$K11/100 -> 0 | BT11: =S11*$K11/100 -> 0 | BU11: =T11*$K11/100 -> 0 | ... CX11: =AW11*$K11/100 -> 0 | DB11: =SUM(BN11:CY11) -> 2.1344276 | DC11: =K11 -> 2.1344276
N12: 4.271 | AA12: 2.941 | BL12: 0 | BN12: =M12*$K11/100 -> 0 | BO12: =N12*$K11/100 -> 0.091161403 | BP12: =O12*$K11/100 -> 0 | BQ12: =P12*$K11/100 -> 0 | BR12: =Q12*$K11/100 -> 0 | BS12: =R12*$K11/100 -> 0 | BT12: =S12*$K11/100 -> 0 | BU12: =T12*$K11/100 -> 0 | ... CX12: =AW12*$K11/100 -> 0 | DB12: =SUM(BN12:CY12) -> 0.15393492 | DC12: =K12 -> 0
A13: -1 | B13: งานคาน | C13: เหมาจ่าย | D13: 1 | E13: =F13*100/SUM(K11:K20) -> 3.1303119 | F13: =K13*SUM(M13:AG13)/100 -> 0.13533034 | G13: =D13*H13/100 -> 0 | H13: =SUM(L14:AJ14) -> 0 | I13: ='BOQ แก้ไขสัญญา'!AF11 -> 2151709 | J13: =D13*I13 -> 2151709 | K13: =J13*100/GTotal -> 0.90220229 | AF13: 5 | AG13: 10 | AH13: 15 | AI13: 15 | AJ13: 15 | AK13: 15 | AL13: 10 | AM13: 10 | AN13: 5 | BL13: 1 | BN13: =M13*$K13/100 -> 0 | BO13: =N13*$K13/100 -> 0 | BP13: =O13*$K13/100 -> 0 | BQ13: =P13*$K13/100 -> 0 | BR13: =Q13*$K13/100 -> 0 | BS13: =R13*$K13/100 -> 0 | BT13: =S13*$K13/100 -> 0 | BU13: =T13*$K13/100 -> 0 | ... CX13: =AW13*$K13/100 -> 0 | DB13: =SUM(BN13:CY13) -> 0.90220229 | DC13: =K13 -> 0.90220229
BL14: 0 | BN14: =M14*$K13/100 -> 0 | BO14: =N14*$K13/100 -> 0 | BP14: =O14*$K13/100 -> 0 | BQ14: =P14*$K13/100 -> 0 | BR14: =Q14*$K13/100 -> 0 | BS14: =R14*$K13/100 -> 0 | BT14: =S14*$K13/100 -> 0 | BU14: =T14*$K13/100 -> 0 | ... CX14: =AW14*$K13/100 -> 0 | DB14: =SUM(BN14:CY14) -> 0 | DC14: =K14 -> 0
A15: -2 | B15: งานกำแพง w15+ บันได | C15: เหมาจ่าย | D15: 1 | E15: =F15*100/SUM(K11:K20) -> 0 | F15: =K15*SUM(M15:AG15)/100 -> 0 | G15: =D15*H15/100 -> 0 | H15: =SUM(L16:AJ16) -> 0 | I15: ='BOQ แก้ไขสัญญา'!AF12 -> 906762 | J15: =D15*I15 -> 906762 | K15: =J15*100/GTotal -> 0.38020139 | AI15: 10 | AJ15: 25 | AK15: 25 | AL15: 25 | AM15: 10 | AN15: 5 | BL15: 1 | BN15: =M15*$K15/100 -> 0 | BO15: =N15*$K15/100 -> 0 | BP15: =O15*$K15/100 -> 0 | BQ15: =P15*$K15/100 -> 0 | BR15: =Q15*$K15/100 -> 0 | BS15: =R15*$K15/100 -> 0 | BT15: =S15*$K15/100 -> 0 | BU15: =T15*$K15/100 -> 0 | ... CX15: =AW15*$K15/100 -> 0 | DB15: =SUM(BN15:CY15) -> 0.38020139 | DC15: =K15 -> 0.38020139
BL16: 0 | BN16: =M16*$K15/100 -> 0 | BO16: =N16*$K15/100 -> 0 | BP16: =O16*$K15/100 -> 0 | BQ16: =P16*$K15/100 -> 0 | BR16: =Q16*$K15/100 -> 0 | BS16: =R16*$K15/100 -> 0 | BT16: =S16*$K15/100 -> 0 | BU16: =T16*$K15/100 -> 0 | ... CX16: =AW16*$K15/100 -> 0 | DB16: =SUM(BN16:CY16) -> 0 | DC16: =K16 -> 0
A17: -3 | B17: งานราวกันตก | C17: เหมาจ่าย | D17: 1 | E17: =F17*100/SUM(K11:K20) -> 0 | F17: =K17*SUM(M17:AG17)/100 -> 0 | G17: =D17*H17/100 -> 0 | H17: =SUM(L18:AJ18) -> 0 | I17: ='BOQ แก้ไขสัญญา'!AF13 -> 1372327 | J17: =D17*I17 -> 1372327 | K17: =J17*100/GTotal -> 0.57541078 | AI17: 10 | AJ17: 25 | AK17: 25 | AL17: 25 | AM17: 10 | AN17: 5 | BL17: 1 | BN17: =M17*$K17/100 -> 0 | BO17: =N17*$K17/100 -> 0 | BP17: =O17*$K17/100 -> 0 | BQ17: =P17*$K17/100 -> 0 | BR17: =Q17*$K17/100 -> 0 | BS17: =R17*$K17/100 -> 0 | BT17: =S17*$K17/100 -> 0 | BU17: =T17*$K17/100 -> 0 | ... CX17: =AW17*$K17/100 -> 0 | DB17: =SUM(BN17:CY17) -> 0.57541078 | DC17: =K17 -> 0.57541078
BL18: 0 | BN18: =M18*$K17/100 -> 0 | BO18: =N18*$K17/100 -> 0 | BP18: =O18*$K17/100 -> 0 | BQ18: =P18*$K17/100 -> 0 | BR18: =Q18*$K17/100 -> 0 | BS18: =R18*$K17/100 -> 0 | BT18: =S18*$K17/100 -> 0 | BU18: =T18*$K17/100 -> 0 | ... CX18: =AW18*$K17/100 -> 0 | DB18: =SUM(BN18:CY18) -> 0 | DC18: =K18 -> 0
A19: -4 | B19: งานวัสดุปูพื้น | C19: เหมาจ่าย | D19: 1 | E19: =F19*100/SUM(K11:K20) -> 0 | F19: =K19*SUM(M19:AG19)/100 -> 0 | G19: =D19*H19/100 -> 0 | H19: =SUM(L20:AJ20) -> 0 | I19: ='BOQ แก้ไขสัญญา'!AF14 -> 789372 | J19: =D19*I19 -> 789372 | K19: =J19*100/GTotal -> 0.33098027 | AJ19: 10 | AK19: 25 | AL19: 25 | AM19: 25 | AN19: 10 | AO19: 5 | BL19: 1 | BN19: =M19*$K19/100 -> 0 | BO19: =N19*$K19/100 -> 0 | BP19: =O19*$K19/100 -> 0 | BQ19: =P19*$K19/100 -> 0 | BR19: =Q19*$K19/100 -> 0 | BS19: =R19*$K19/100 -> 0 | BT19: =S19*$K19/100 -> 0 | BU19: =T19*$K19/100 -> 0 | ... CX19: =AW19*$K19/100 -> 0 | DB19: =SUM(BN19:CY19) -> 0.33098027 | DC19: =K19 -> 0.33098027
AZ20: 90 | BL20: 0 | BN20: =M20*$K19/100 -> 0 | BO20: =N20*$K19/100 -> 0 | BP20: =O20*$K19/100 -> 0 | BQ20: =P20*$K19/100 -> 0 | BR20: =Q20*$K19/100 -> 0 | BS20: =R20*$K19/100 -> 0 | BT20: =S20*$K19/100 -> 0 | BU20: =T20*$K19/100 -> 0 | ... CX20: =AW20*$K19/100 -> 0 | DB20: =SUM(BN20:CY20) -> 0 | DC20: =K20 -> 0
A21: 1.2 | B21: งานเขื่อนป้องกันตลิ่ง แบบที่ 2 | C21: เหมาจ่าย | D21: 1 | E21: =F21*100/SUM($K$21:$K$28) -> 0 | F21: =K21*SUM(M21:AG21)/100 -> 0 | G21: =D21*H21/100 -> 0.00348 | H21: =SUM(L22:AJ22) -> 0.348 | I21: ='BOQ แก้ไขสัญญา'!AF16 -> 5004503 | J21: =D21*I21 -> 5004503 | K21: =J21*100/GTotal -> 2.0983665 | AK21: 5 | AL21: 5 | AM21: 10 | AN21: 10 | AO21: 10 | AP21: 10 | AQ21: 10 | AR21: 10 | AS21: 10 | AT21: 10 | AU21: 10 | BL21: 1 | BN21: =M21*$K21/100 -> 0 | BO21: =N21*$K21/100 -> 0 | BP21: =O21*$K21/100 -> 0 | BQ21: =P21*$K21/100 -> 0 | BR21: =Q21*$K21/100 -> 0 | BS21: =R21*$K21/100 -> 0 | BT21: =S21*$K21/100 -> 0 | BU21: =T21*$K21/100 -> 0 | ... CX21: =AW21*$K21/100 -> 0 | DB21: =SUM(BN21:CY21) -> 2.0983665 | DC21: =K21 -> 2.0983665
N22: 0.348 | BL22: 0 | BN22: =M22*$K21/100 -> 0 | BO22: =N22*$K21/100 -> 0.0073023154 | BP22: =O22*$K21/100 -> 0 | BQ22: =P22*$K21/100 -> 0 | BR22: =Q22*$K21/100 -> 0 | BS22: =R22*$K21/100 -> 0 | BT22: =S22*$K21/100 -> 0 | BU22: =T22*$K21/100 -> 0 | ... CX22: =AW22*$K21/100 -> 0 | DB22: =SUM(BN22:CY22) -> 0.0073023154 | DC22: =K22 -> 0
A23: -1 | B23: งานคาน | C23: เหมาจ่าย | D23: 1 | E23: =F23*100/SUM($K$21:$K$28) -> 0 | F23: =K23*SUM(M23:AG23)/100 -> 0 | H23: =SUM(L24:AJ24) -> 0 | I23: ='BOQ แก้ไขสัญญา'!AF17 -> 1136018 | J23: =D23*I23 -> 1136018 | K23: =J23*100/GTotal -> 0.47632744 | AM23: 10 | AN23: 10 | AO23: 10 | AP23: 10 | AQ23: 20 | AR23: 20 | AS23: 20 | BL23: 1 | BN23: =M23*$K23/100 -> 0 | BO23: =N23*$K23/100 -> 0 | BP23: =O23*$K23/100 -> 0 | BQ23: =P23*$K23/100 -> 0 | BR23: =Q23*$K23/100 -> 0 | BS23: =R23*$K23/100 -> 0 | BT23: =S23*$K23/100 -> 0 | BU23: =T23*$K23/100 -> 0 | ... CX23: =AW23*$K23/100 -> 0 | DB23: =SUM(BN23:CY23) -> 0.47632744 | DC23: =K23 -> 0.47632744
BL24: 0 | BN24: =M24*$K23/100 -> 0 | BO24: =N24*$K23/100 -> 0 | BP24: =O24*$K23/100 -> 0 | BQ24: =P24*$K23/100 -> 0 | BR24: =Q24*$K23/100 -> 0 | BS24: =R24*$K23/100 -> 0 | BT24: =S24*$K23/100 -> 0 | BU24: =T24*$K23/100 -> 0 | ... CX24: =AW24*$K23/100 -> 0 | DB24: =SUM(BN24:CY24) -> 0 | DC24: =K24 -> 0
A25: -2 | B25: งานราวกันตก | C25: เหมาจ่าย | D25: 1 | E25: =F25*100/SUM($K$21:$K$28) -> 0 | F25: =K25*SUM(M25:AG25)/100 -> 0 | H25: =SUM(L26:AJ26) -> 0 | I25: ='BOQ แก้ไขสัญญา'!AF18 -> 528774 | J25: =D25*I25 -> 528774 | K25: =J25*100/GTotal -> 0.22171265 | AM25: 10 | AN25: 15 | AO25: 15 | AP25: 15 | AQ25: 15 | AR25: 15 | AS25: 15 | BL25: 1 | BN25: =M25*$K25/100 -> 0 | BO25: =N25*$K25/100 -> 0 | BP25: =O25*$K25/100 -> 0 | BQ25: =P25*$K25/100 -> 0 | BR25: =Q25*$K25/100 -> 0 | BS25: =R25*$K25/100 -> 0 | BT25: =S25*$K25/100 -> 0 | BU25: =T25*$K25/100 -> 0 | ... CX25: =AW25*$K25/100 -> 0 | DB25: =SUM(BN25:CY25) -> 0.22171265 | DC25: =K25 -> 0.22171265
BL26: 0 | BN26: =M26*$K25/100 -> 0 | BO26: =N26*$K25/100 -> 0 | BP26: =O26*$K25/100 -> 0 | BQ26: =P26*$K25/100 -> 0 | BR26: =Q26*$K25/100 -> 0 | BS26: =R26*$K25/100 -> 0 | BT26: =S26*$K25/100 -> 0 | BU26: =T26*$K25/100 -> 0 | ... CX26: =AW26*$K25/100 -> 0 | DB26: =SUM(BN26:CY26) -> 0 | DC26: =K26 -> 0
A27: -3 | B27: งานระบายน้ำหลังเขื่อน | C27: เหมาจ่าย | D27: 1 | E27: =F27*100/SUM($K$21:$K$28) -> 0 | F27: =K27*SUM(M27:AG27)/100 -> 0 | H27: =SUM(L28:AJ28) -> 0 | I27: ='BOQ แก้ไขสัญญา'!AF19 -> 160623 | J27: =D27*I27 -> 160623 | K27: =J27*100/GTotal -> 0.06734853 | AM27: 5 | AN27: 10 | AO27: 10 | AP27: 15 | AQ27: 15 | AR27: 15 | AS27: 30 | BL27: 1 | BN27: =M27*$K27/100 -> 0 | BO27: =N27*$K27/100 -> 0 | BP27: =O27*$K27/100 -> 0 | BQ27: =P27*$K27/100 -> 0 | BR27: =Q27*$K27/100 -> 0 | BS27: =R27*$K27/100 -> 0 | BT27: =S27*$K27/100 -> 0 | BU27: =T27*$K27/100 -> 0 | ... CX27: =AW27*$K27/100 -> 0 | DB27: =SUM(BN27:CY27) -> 0.06734853 | DC27: =K27 -> 0.06734853
BL28: 0 | BN28: =M28*$K27/100 -> 0 | BO28: =N28*$K27/100 -> 0 | BP28: =O28*$K27/100 -> 0 | BQ28: =P28*$K27/100 -> 0 | BR28: =Q28*$K27/100 -> 0 | BS28: =R28*$K27/100 -> 0 | BT28: =S28*$K27/100 -> 0 | BU28: =T28*$K27/100 -> 0 | ... CX28: =AW28*$K27/100 -> 0 | DB28: =SUM(BN28:CY28) -> 0 | DC28: =K28 -> 0
A29: 1.3 | B29: งานเขื่อนป้องกันตลิ่ง แบบที่ 1 | C29: เหมาจ่าย | D29: 1 | E29: =F29*100/SUM($K$29:$K$38) -> 0 | F29: =K29*SUM(M29:AG29)/100 -> 0 | H29: =SUM(L30:AJ30) -> 64.766 | I29: ='BOQ แก้ไขสัญญา'!AF21 -> 4270013 | J29: =D29*I29 -> 4270013 | K29: =J29*100/GTotal -> 1.790398 | AB29: 0 | AH29: 5 | AI29: 5 | AJ29: 10 | AK29: 10 | AL29: 10 | AM29: 10 | AN29: 10 | AO29: 10 | AP29: 10 | AQ29: 10 | AR29: 10 | BL29: 1 | BN29: =M29*$K29/100 -> 0 | BO29: =N29*$K29/100 -> 0 | BP29: =O29*$K29/100 -> 0 | BQ29: =P29*$K29/100 -> 0 | BR29: =Q29*$K29/100 -> 0 | BS29: =R29*$K29/100 -> 0 | BT29: =S29*$K29/100 -> 0 | BU29: =T29*$K29/100 -> 0 | ... CX29: =AW29*$K29/100 -> 0 | DB29: =SUM(BN29:CY29) -> 1.790398 | DC29: =K29 -> 1.790398
N30: 0.407 | AB30: 29.02 | AG30: =64.766-N30-AB30 -> 35.339 | AZ30: 80 | BL30: 0 | BN30: =M30*$K29/100 -> 0 | BO30: =N30*$K29/100 -> 0.0072869199 | BP30: =O30*$K29/100 -> 0 | BQ30: =P30*$K29/100 -> 0 | BR30: =Q30*$K29/100 -> 0 | BS30: =R30*$K29/100 -> 0 | BT30: =S30*$K29/100 -> 0 | BU30: =T30*$K29/100 -> 0 | ... CX30: =AW30*$K29/100 -> 0 | DB30: =SUM(BN30:CY30) -> 1.1595692 | DC30: =K30 -> 0
A31: -1 | B31: งานคาน | C31: เหมาจ่าย | D31: 1 | E31: =F31*100/SUM($K$29:$K$38) -> 0 | F31: =K31*SUM(M31:AG31)/100 -> 0 | H31: =SUM(L32:AJ32) -> 0 | I31: ='BOQ แก้ไขสัญญา'!AF22 -> 2092762 | J31: =D31*I31 -> 2092762 | K31: =J31*100/GTotal -> 0.87748607 | AH31: 0 | AI31: 5 | AJ31: 10 | AK31: 15 | AL31: 15 | AM31: 15 | AN31: 15 | AO31: 10 | AP31: 10 | AQ31: 5 | BL31: 1 | BN31: =M31*$K31/100 -> 0 | BO31: =N31*$K31/100 -> 0 | BP31: =O31*$K31/100 -> 0 | BQ31: =P31*$K31/100 -> 0 | BR31: =Q31*$K31/100 -> 0 | BS31: =R31*$K31/100 -> 0 | BT31: =S31*$K31/100 -> 0 | BU31: =T31*$K31/100 -> 0 | ... CX31: =AW31*$K31/100 -> 0 | DB31: =SUM(BN31:CY31) -> 0.87748607 | DC31: =K31 -> 0.87748607
BL32: 0 | BN32: =M32*$K31/100 -> 0 | BO32: =N32*$K31/100 -> 0 | BP32: =O32*$K31/100 -> 0 | BQ32: =P32*$K31/100 -> 0 | BR32: =Q32*$K31/100 -> 0 | BS32: =R32*$K31/100 -> 0 | BT32: =S32*$K31/100 -> 0 | BU32: =T32*$K31/100 -> 0 | ... CX32: =AW32*$K31/100 -> 0 | DB32: =SUM(BN32:CY32) -> 0 | DC32: =K32 -> 0
A33: -2 | B33: งานกำแพง w15+ บันได | C33: เหมาจ่าย | D33: 1 | E33: =F33*100/SUM($K$29:$K$38) -> 0 | F33: =K33*SUM(M33:AG33)/100 -> 0 | H33: =SUM(L34:AJ34) -> 0 | I33: ='BOQ แก้ไขสัญญา'!AF23 -> 883548 | J33: =D33*I33 -> 883548 | K33: =J33*100/GTotal -> 0.37046786 | AI33: 0 | AJ33: 5 | AK33: 5 | AL33: 15 | AM33: 15 | AN33: 15 | AO33: 15 | AP33: 15 | AQ33: 15 | BL33: 1 | BN33: =M33*$K33/100 -> 0 | BO33: =N33*$K33/100 -> 0 | BP33: =O33*$K33/100 -> 0 | BQ33: =P33*$K33/100 -> 0 | BR33: =Q33*$K33/100 -> 0 | BS33: =R33*$K33/100 -> 0 | BT33: =S33*$K33/100 -> 0 | BU33: =T33*$K33/100 -> 0 | ... CX33: =AW33*$K33/100 -> 0 | DB33: =SUM(BN33:CY33) -> 0.37046786 | DC33: =K33 -> 0.37046786
BL34: 0 | BN34: =M34*$K33/100 -> 0 | BO34: =N34*$K33/100 -> 0 | BP34: =O34*$K33/100 -> 0 | BQ34: =P34*$K33/100 -> 0 | BR34: =Q34*$K33/100 -> 0 | BS34: =R34*$K33/100 -> 0 | BT34: =S34*$K33/100 -> 0 | BU34: =T34*$K33/100 -> 0 | ... CX34: =AW34*$K33/100 -> 0 | DB34: =SUM(BN34:CY34) -> 0 | DC34: =K34 -> 0
A35: -3 | B35: งานราวกันตก | C35: เหมาจ่าย | D35: 1 | E35: =F35*100/SUM($K$29:$K$38) -> 0 | F35: =K35*SUM(M35:AG35)/100 -> 0 | H35: =SUM(L36:AJ36) -> 0 | I35: ='BOQ แก้ไขสัญญา'!AF24 -> 1344618 | J35: =D35*I35 -> 1344618 | K35: =J35*100/GTotal -> 0.56379252 | AJ35: 0 | AK35: 10 | AL35: 10 | AM35: 20 | AN35: 20 | AO35: 20 | AP35: 20 | BL35: 1 | BN35: =M35*$K35/100 -> 0 | BO35: =N35*$K35/100 -> 0 | BP35: =O35*$K35/100 -> 0 | BQ35: =P35*$K35/100 -> 0 | BR35: =Q35*$K35/100 -> 0 | BS35: =R35*$K35/100 -> 0 | BT35: =S35*$K35/100 -> 0 | BU35: =T35*$K35/100 -> 0 | ... CX35: =AW35*$K35/100 -> 0 | DB35: =SUM(BN35:CY35) -> 0.56379252 | DC35: =K35 -> 0.56379252
BL36: 0 | BN36: =M36*$K35/100 -> 0 | BO36: =N36*$K35/100 -> 0 | BP36: =O36*$K35/100 -> 0 | BQ36: =P36*$K35/100 -> 0 | BR36: =Q36*$K35/100 -> 0 | BS36: =R36*$K35/100 -> 0 | BT36: =S36*$K35/100 -> 0 | BU36: =T36*$K35/100 -> 0 | ... CX36: =AW36*$K35/100 -> 0 | DB36: =SUM(BN36:CY36) -> 0 | DC36: =K36 -> 0
A37: -4 | B37: งานวัสดุปูพื้น | C37: เหมาจ่าย | D37: 1 | E37: =F37*100/SUM($K$29:$K$38) -> 0 | F37: =K37*SUM(M37:AG37)/100 -> 0 | H37: =SUM(L38:AJ38) -> 0 | I37: ='BOQ แก้ไขสัญญา'!AF25 -> 1048108 | J37: =D37*I37 -> 1048108 | K37: =J37*100/GTotal -> 0.43946716 | AL37: 10 | AM37: 10 | AN37: 20 | AO37: 20 | AP37: 20 | AQ37: 20 | BL37: 1 | BN37: =M37*$K37/100 -> 0 | BO37: =N37*$K37/100 -> 0 | BP37: =O37*$K37/100 -> 0 | BQ37: =P37*$K37/100 -> 0 | BR37: =Q37*$K37/100 -> 0 | BS37: =R37*$K37/100 -> 0 | BT37: =S37*$K37/100 -> 0 | BU37: =T37*$K37/100 -> 0 | ... CX37: =AW37*$K37/100 -> 0 | DB37: =SUM(BN37:CY37) -> 0.43946716 | DC37: =K37 -> 0.43946716
BL38: 0 | BN38: =M38*$K37/100 -> 0 | BO38: =N38*$K37/100 -> 0 | BP38: =O38*$K37/100 -> 0 | BQ38: =P38*$K37/100 -> 0 | BR38: =Q38*$K37/100 -> 0 | BS38: =R38*$K37/100 -> 0 | BT38: =S38*$K37/100 -> 0 | BU38: =T38*$K37/100 -> 0 | ... CX38: =AW38*$K37/100 -> 0 | DB38: =SUM(BN38:CY38) -> 0 | DC38: =K38 -> 0
A39: 1.4 | B39: งานเขื่อนป้องกันตลิ่ง แบบที่ 4 ช่วงที่ 1 | C39: เหมาจ่าย | D39: 1 | E39: =F39*100/SUM($K$39:$K$44) -> 0 | F39: =K39*SUM(M39:AG39)/100 -> 0 | H39: =SUM(L40:AJ40) -> 53.669 | I39: ='BOQ แก้ไขสัญญา'!AF27 -> 2827285 | J39: =D39*I39 -> 2827285 | K39: =J39*100/GTotal -> 1.1854684 | AK39: 10 | AL39: 10 | AM39: 10 | AN39: 20 | AO39: 20 | AP39: 20 | AQ39: 10 | BL39: 1 | BN39: =M39*$K39/100 -> 0 | BO39: =N39*$K39/100 -> 0 | BP39: =O39*$K39/100 -> 0 | BQ39: =P39*$K39/100 -> 0 | BR39: =Q39*$K39/100 -> 0 | BS39: =R39*$K39/100 -> 0 | BT39: =S39*$K39/100 -> 0 | BU39: =T39*$K39/100 -> 0 | ... CX39: =AW39*$K39/100 -> 0 | DB39: =SUM(BN39:CY39) -> 1.1854684 | DC39: =K39 -> 1.1854684
N40: 0.615 | AA40: 53.054 | AZ40: 70 | BL40: 0 | BN40: =M40*$K39/100 -> 0 | BO40: =N40*$K39/100 -> 0.0072906306 | BP40: =O40*$K39/100 -> 0 | BQ40: =P40*$K39/100 -> 0 | BR40: =Q40*$K39/100 -> 0 | BS40: =R40*$K39/100 -> 0 | BT40: =S40*$K39/100 -> 0 | BU40: =T40*$K39/100 -> 0 | ... CX40: =AW40*$K39/100 -> 0 | DB40: =SUM(BN40:CY40) -> 0.63622903 | DC40: =K40 -> 0
A41: -1 | B41: งานคาน | C41: เหมาจ่าย | D41: 1 | E41: =F41*100/SUM($K$39:$K$44) -> 0 | F41: =K41*SUM(M41:AG41)/100 -> 0 | H41: =SUM(L42:AJ42) -> 0 | I41: ='BOQ แก้ไขสัญญา'!AF28 -> 317663 | J41: =D41*I41 -> 317663 | K41: =J41*100/GTotal -> 0.13319472 | AN41: 25 | AO41: 25 | AP41: 25 | AQ41: 25 | BL41: 1 | BN41: =M41*$K41/100 -> 0 | BO41: =N41*$K41/100 -> 0 | BP41: =O41*$K41/100 -> 0 | BQ41: =P41*$K41/100 -> 0 | BR41: =Q41*$K41/100 -> 0 | BS41: =R41*$K41/100 -> 0 | BT41: =S41*$K41/100 -> 0 | BU41: =T41*$K41/100 -> 0 | ... CX41: =AW41*$K41/100 -> 0 | DB41: =SUM(BN41:CY41) -> 0.13319472 | DC41: =K41 -> 0.13319472
BL42: 0 | BN42: =M42*$K41/100 -> 0 | BO42: =N42*$K41/100 -> 0 | BP42: =O42*$K41/100 -> 0 | BQ42: =P42*$K41/100 -> 0 | BR42: =Q42*$K41/100 -> 0 | BS42: =R42*$K41/100 -> 0 | BT42: =S42*$K41/100 -> 0 | BU42: =T42*$K41/100 -> 0 | ... CX42: =AW42*$K41/100 -> 0 | DB42: =SUM(BN42:CY42) -> 0 | DC42: =K42 -> 0
A43: -2 | B43: งานราวกันตก และ งานระบายน้ำหลังเขื่อน | C43: เหมาจ่าย | D43: 1 | E43: =F43*100/SUM($K$39:$K$44) -> 0 | F43: =K43*SUM(M43:AG43)/100 -> 0 | H43: =SUM(L44:AJ44) -> 0 | I43: ='BOQ แก้ไขสัญญา'!AF29 -> 262286 | J43: =D43*I43 -> 262286 | K43: =J43*100/GTotal -> 0.10997539 | AO43: 30 | AP43: 30 | AQ43: 40 | BL43: 1 | BN43: =M43*$K43/100 -> 0 | BO43: =N43*$K43/100 -> 0 | BP43: =O43*$K43/100 -> 0 | BQ43: =P43*$K43/100 -> 0 | BR43: =Q43*$K43/100 -> 0 | BS43: =R43*$K43/100 -> 0 | BT43: =S43*$K43/100 -> 0 | BU43: =T43*$K43/100 -> 0 | ... CX43: =AW43*$K43/100 -> 0 | DB43: =SUM(BN43:CY43) -> 0.10997539 | DC43: =K43 -> 0.10997539
BL44: 0 | BN44: =M44*$K43/100 -> 0 | BO44: =N44*$K43/100 -> 0 | BP44: =O44*$K43/100 -> 0 | BQ44: =P44*$K43/100 -> 0 | BR44: =Q44*$K43/100 -> 0 | BS44: =R44*$K43/100 -> 0 | BT44: =S44*$K43/100 -> 0 | BU44: =T44*$K43/100 -> 0 | ... CX44: =AW44*$K43/100 -> 0 | DB44: =SUM(BN44:CY44) -> 0 | DC44: =K44 -> 0
A45: 1.5 | B45: งานเขื่อนป้องกันตลิ่ง แบบที่ 4 ช่วงที่ 2 | C45: เหมาจ่าย | D45: 1 | E45: =F45*100/SUM($K$45:$K$50) -> 0 | F45: =K45*SUM(M45:AG45)/100 -> 0 | H45: =SUM(L46:AJ46) -> 54.391 | I45: ='BOQ แก้ไขสัญญา'!AF31 -> 3175884 | J45: =D45*I45 -> 3175884 | K45: =J45*100/GTotal -> 1.3316344 | AO45: 10 | AP45: 10 | AQ45: 10 | AR45: 20 | AS45: 20 | AT45: 20 | AU45: 10 | BL45: 1 | BN45: =M45*$K45/100 -> 0 | BO45: =N45*$K45/100 -> 0 | BP45: =O45*$K45/100 -> 0 | BQ45: =P45*$K45/100 -> 0 | BR45: =Q45*$K45/100 -> 0 | BS45: =R45*$K45/100 -> 0 | BT45: =S45*$K45/100 -> 0 | BU45: =T45*$K45/100 -> 0 | ... CX45: =AW45*$K45/100 -> 0 | DB45: =SUM(BN45:CY45) -> 1.3316344 | DC45: =K45 -> 1.3316344
N46: 0.548 | AA46: 17.003 | AB46: 36.84 | BL46: 0 | BN46: =M46*$K45/100 -> 0 | BO46: =N46*$K45/100 -> 0.0072973567 | BP46: =O46*$K45/100 -> 0 | BQ46: =P46*$K45/100 -> 0 | BR46: =Q46*$K45/100 -> 0 | BS46: =R46*$K45/100 -> 0 | BT46: =S46*$K45/100 -> 0 | BU46: =T46*$K45/100 -> 0 | ... CX46: =AW46*$K45/100 -> 0 | DB46: =SUM(BN46:CY46) -> 0.72428929 | DC46: =K46 -> 0
A47: -1 | B47: งานคาน | C47: เหมาจ่าย | D47: 1 | E47: =F47*100/SUM($K$45:$K$50) -> 0 | F47: =K47*SUM(M47:AG47)/100 -> 0 | H47: =SUM(L48:AJ48) -> 0 | I47: ='BOQ แก้ไขสัญญา'!AF32 -> 358105 | J47: =D47*I47 -> 358105 | K47: =J47*100/GTotal -> 0.15015188 | AR47: 25 | AS47: 25 | AT47: 25 | AU47: 25 | BL47: 1 | BN47: =M47*$K47/100 -> 0 | BO47: =N47*$K47/100 -> 0 | BP47: =O47*$K47/100 -> 0 | BQ47: =P47*$K47/100 -> 0 | BR47: =Q47*$K47/100 -> 0 | BS47: =R47*$K47/100 -> 0 | BT47: =S47*$K47/100 -> 0 | BU47: =T47*$K47/100 -> 0 | ... CX47: =AW47*$K47/100 -> 0 | DB47: =SUM(BN47:CY47) -> 0.15015188 | DC47: =K47 -> 0.15015188
...

Sheet ผลงานรายสัปดาห์(%)
B2: ลำดับ | C2: รายการ | D2: หน่วย | E2: ปริมาณ | F2: ผลงาน | G2: % | H2: ราคาต่อหน่วย | I2: จำนวนเงิน | J2: % | L2: สะสมสัปดาก่อน (%) | M2: สะสมสัปดานี้ (%) | O2: รายการ | P2: 2567 | U2: 2568
B3: ที่ | H3: (บาท) | I3: (บาท) | P3: 243831 | U3: เดือนกันยายน | Z3: เดือนตุลาคม | AE3: เดือนพฤศจิกายน | AJ3: เดือนธันวาคม | AO3: เดือนมกราคม
B4: 1 | C4: งานเขื่อนป้องกันตลิ่ง | F4: =[1]แผนการก่อสร้าง!E9 -> 0 | G4: =[1]แผนการก่อสร้าง!F9 -> 0 | O4: งานเขื่อนป้องกันตลิ่ง | P4: 1 - 7 | Q4: 8 - 15 | R4: 16 - 23 | S4: 24 - 30 | T4: รวม | U4: 1 - 7 | V4: 8 - 15 | W4: 16 - 23 | X4: 24 - 30 | Y4: รวม | Z4: 1 - 7 | AA4: 8 - 15 | AB4: 16 - 23 | AC4: 24 - 30 | AD4: รวม | AE4: 1 - 7 | AF4: 8 - 15 | AG4: 16 - 23 | AH4: 24 - 30 | AI4: รวม | AJ4: 1 - 7 | AK4: 8 - 15 | AL4: 16 - 23 | AM4: 24 - 30 | AN4: รวม | AO4: 1 - 7 | AP4: 8 - 15 | AQ4: 16 - 23 | AR4: 24 - 30 | AS4: รวม
B6: 1.1 | C6: งานเขื่อนป้องกันตลิ่ง แบบที่ 1 | D6: เหมาจ่าย | E6: 1 | F6: =แผนการก่อสร้าง!G11 -> 0.07212 | G6: =แผนการก่อสร้าง!H11 -> 7.212 | H6: 5090507 | I6: 5090507 | J6: 2.1344276 | O6: งานเขื่อนป้องกันตลิ่ง แบบที่ 1
L7: =('ผลงานรายสัปดาห์(เงิน)'!L7)*100/$I6 -> 7.2172379 | M7: =('ผลงานรายสัปดาห์(เงิน)'!M7)*100/$I6 -> 7.2172379 | P7: =('ผลงานรายสัปดาห์(เงิน)'!P7)*100/$I6 -> 0 | Q7: =('ผลงานรายสัปดาห์(เงิน)'!Q7)*100/$I6 -> 0 | R7: =('ผลงานรายสัปดาห์(เงิน)'!R7)*100/$I6 -> 0 | S7: =('ผลงานรายสัปดาห์(เงิน)'!S7)*100/$I6 -> 4.2705766 | T7: 217394 | U7: =('ผลงานรายสัปดาห์(เงิน)'!U7)*100/$I6 -> 0 | V7: =('ผลงานรายสัปดาห์(เงิน)'!V7)*100/$I6 -> 0 | W7: =('ผลงานรายสัปดาห์(เงิน)'!W7)*100/$I6 -> 2.9466613 | X7: =('ผลงานรายสัปดาห์(เงิน)'!X7)*100/$I6 -> 0 | Y7: =SUM(U7:X7) -> 2.9466613 | Z7: =('ผลงานรายสัปดาห์(เงิน)'!Z7)*100/$I6 -> 0 | AA7: =('ผลงานรายสัปดาห์(เงิน)'!AA7)*100/$I6 -> 0 | AB7: =('ผลงานรายสัปดาห์(เงิน)'!AB7)*100/$I6 -> 0 | AC7: =('ผลงานรายสัปดาห์(เงิน)'!AC7)*100/$I6 -> 0 | AD7: =SUM(Z7:AC7) -> 0 | AE7: =('ผลงานรายสัปดาห์(เงิน)'!AE7)*100/$I6 -> 0 | AF7: =('ผลงานรายสัปดาห์(เงิน)'!AF7)*100/$I6 -> 0 | AG7: =('ผลงานรายสัปดาห์(เงิน)'!AG7)*100/$I6 -> 0 | AH7: =('ผลงานรายสัปดาห์(เงิน)'!AH7)*100/$I6 -> 0 | AI7: =SUM(AE7:AH7) -> 0 | AJ7: =('ผลงานรายสัปดาห์(เงิน)'!AJ7)*100/$I6 -> 0 | AK7: =('ผลงานรายสัปดาห์(เงิน)'!AK7)*100/$I6 -> 0 | AL7: =('ผลงานรายสัปดาห์(เงิน)'!AL7)*100/$I6 -> 0 | AM7: =('ผลงานรายสัปดาห์(เงิน)'!AM7)*100/$I6 -> 0
B8: -1 | C8: งานคาน | D8: เหมาจ่าย | E8: 1 | F8: =แผนการก่อสร้าง!G13 -> 0 | G8: =แผนการก่อสร้าง!H13 -> 0 | H8: 2151709 | I8: 2151709 | J8: 0.90220229 | O8: งานคาน
L9: =('ผลงานรายสัปดาห์(เงิน)'!L9)*100/$I8 -> 0 | M9: =('ผลงานรายสัปดาห์(เงิน)'!M9)*100/$I8 -> 0 | P9: =('ผลงานรายสัปดาห์(เงิน)'!P9)*100/$I8 -> 0 | Q9: =('ผลงานรายสัปดาห์(เงิน)'!Q9)*100/$I8 -> 0 | R9: =('ผลงานรายสัปดาห์(เงิน)'!R9)*100/$I8 -> 0 | S9: =('ผลงานรายสัปดาห์(เงิน)'!S9)*100/$I8 -> 0 | T9: =SUM(P9:S9) -> 0 | U9: =('ผลงานรายสัปดาห์(เงิน)'!U9)*100/$I8 -> 0 | V9: =('ผลงานรายสัปดาห์(เงิน)'!V9)*100/$I8 -> 0 | W9: =('ผลงานรายสัปดาห์(เงิน)'!W9)*100/$I8 -> 0 | X9: =('ผลงานรายสัปดาห์(เงิน)'!X9)*100/$I8 -> 0 | Y9: 0 | Z9: =('ผลงานรายสัปดาห์(เงิน)'!Z9)*100/$I8 -> 0 | AA9: =('ผลงานรายสัปดาห์(เงิน)'!AA9)*100/$I8 -> 0 | AB9: =('ผลงานรายสัปดาห์(เงิน)'!AB9)*100/$I8 -> 0 | AC9: =('ผลงานรายสัปดาห์(เงิน)'!AC9)*100/$I8 -> 0 | AD9: 0 | AE9: =('ผลงานรายสัปดาห์(เงิน)'!AE9)*100/$I8 -> 0 | AF9: =('ผลงานรายสัปดาห์(เงิน)'!AF9)*100/$I8 -> 0 | AG9: =('ผลงานรายสัปดาห์(เงิน)'!AG9)*100/$I8 -> 0 | AH9: =('ผลงานรายสัปดาห์(เงิน)'!AH9)*100/$I8 -> 0 | AI9: 0 | AJ9: =('ผลงานรายสัปดาห์(เงิน)'!AJ9)*100/$I8 -> 0 | AK9: =('ผลงานรายสัปดาห์(เงิน)'!AK9)*100/$I8 -> 0 | AL9: =('ผลงานรายสัปดาห์(เงิน)'!AL9)*100/$I8 -> 0 | AM9: =('ผลงานรายสัปดาห์(เงิน)'!AM9)*100/$I8 -> 0
B10: -2 | C10: งานกำแพง w15+ บันได | D10: เหมาจ่าย | E10: 1 | F10: =แผนการก่อสร้าง!G15 -> 0 | G10: =แผนการก่อสร้าง!H15 -> 0 | H10: 906762 | I10: 906762 | J10: 0.38020139 | O10: งานกำแพง w15+ บันได
L11: =('ผลงานรายสัปดาห์(เงิน)'!L11)*100/$I10 -> 0 | M11: =('ผลงานรายสัปดาห์(เงิน)'!M11)*100/$I10 -> 0 | P11: =('ผลงานรายสัปดาห์(เงิน)'!P11)*100/$I10 -> 0 | Q11: =('ผลงานรายสัปดาห์(เงิน)'!Q11)*100/$I10 -> 0 | R11: =('ผลงานรายสัปดาห์(เงิน)'!R11)*100/$I10 -> 0 | S11: =('ผลงานรายสัปดาห์(เงิน)'!S11)*100/$I10 -> 0 | T11: =SUM(P11:S11) -> 0 | U11: =('ผลงานรายสัปดาห์(เงิน)'!U11)*100/$I10 -> 0 | V11: =('ผลงานรายสัปดาห์(เงิน)'!V11)*100/$I10 -> 0 | W11: =('ผลงานรายสัปดาห์(เงิน)'!W11)*100/$I10 -> 0 | X11: =('ผลงานรายสัปดาห์(เงิน)'!X11)*100/$I10 -> 0 | Y11: =SUM(U11:X11) -> 0 | Z11: =('ผลงานรายสัปดาห์(เงิน)'!Z11)*100/$I10 -> 0 | AA11: =('ผลงานรายสัปดาห์(เงิน)'!AA11)*100/$I10 -> 0 | AB11: =('ผลงานรายสัปดาห์(เงิน)'!AB11)*100/$I10 -> 0 | AC11: =('ผลงานรายสัปดาห์(เงิน)'!AC11)*100/$I10 -> 0 | AD11: =SUM(Z11:AC11) -> 0 | AE11: =('ผลงานรายสัปดาห์(เงิน)'!AE11)*100/$I10 -> 0 | AF11: =('ผลงานรายสัปดาห์(เงิน)'!AF11)*100/$I10 -> 0 | AG11: =('ผลงานรายสัปดาห์(เงิน)'!AG11)*100/$I10 -> 0 | AH11: =('ผลงานรายสัปดาห์(เงิน)'!AH11)*100/$I10 -> 0 | AI11: =SUM(AE11:AH11) -> 0 | AJ11: =('ผลงานรายสัปดาห์(เงิน)'!AJ11)*100/$I10 -> 0 | AK11: =('ผลงานรายสัปดาห์(เงิน)'!AK11)*100/$I10 -> 0 | AL11: =('ผลงานรายสัปดาห์(เงิน)'!AL11)*100/$I10 -> 0 | AM11: =('ผลงานรายสัปดาห์(เงิน)'!AM11)*100/$I10 -> 0
B12: -3 | C12: งานราวกันตก | D12: เหมาจ่าย | E12: 1 | F12: =แผนการก่อสร้าง!G17 -> 0 | G12: =แผนการก่อสร้าง!H17 -> 0 | H12: 1372327 | I12: 1372327 | J12: 0.57541078 | O12: งานราวกันตก
L13: =('ผลงานรายสัปดาห์(เงิน)'!L13)*100/$I12 -> 0 | M13: =('ผลงานรายสัปดาห์(เงิน)'!M13)*100/$I12 -> 0 | P13: =('ผลงานรายสัปดาห์(เงิน)'!P13)*100/$I12 -> 0 | Q13: =('ผลงานรายสัปดาห์(เงิน)'!Q13)*100/$I12 -> 0 | R13: =('ผลงานรายสัปดาห์(เงิน)'!R13)*100/$I12 -> 0 | S13: =('ผลงานรายสัปดาห์(เงิน)'!S13)*100/$I12 -> 0 | T13: =SUM(P13:S13) -> 0 | U13: =('ผลงานรายสัปดาห์(เงิน)'!U13)*100/$I12 -> 0 | V13: =('ผลงานรายสัปดาห์(เงิน)'!V13)*100/$I12 -> 0 | W13: =('ผลงานรายสัปดาห์(เงิน)'!W13)*100/$I12 -> 0 | X13: =('ผลงานรายสัปดาห์(เงิน)'!X13)*100/$I12 -> 0 | Y13: =SUM(U13:X13) -> 0 | Z13: =('ผลงานรายสัปดาห์(เงิน)'!Z13)*100/$I12 -> 0 | AA13: =('ผลงานรายสัปดาห์(เงิน)'!AA13)*100/$I12 -> 0 | AB13: =('ผลงานรายสัปดาห์(เงิน)'!AB13)*100/$I12 -> 0 | AC13: =('ผลงานรายสัปดาห์(เงิน)'!AC13)*100/$I12 -> 0 | AD13: =SUM(Z13:AC13) -> 0 | AE13: =('ผลงานรายสัปดาห์(เงิน)'!AE13)*100/$I12 -> 0 | AF13: =('ผลงานรายสัปดาห์(เงิน)'!AF13)*100/$I12 -> 0 | AG13: =('ผลงานรายสัปดาห์(เงิน)'!AG13)*100/$I12 -> 0 | AH13: =('ผลงานรายสัปดาห์(เงิน)'!AH13)*100/$I12 -> 0 | AI13: =SUM(AE13:AH13) -> 0 | AJ13: =('ผลงานรายสัปดาห์(เงิน)'!AJ13)*100/$I12 -> 0 | AK13: =('ผลงานรายสัปดาห์(เงิน)'!AK13)*100/$I12 -> 0 | AL13: =('ผลงานรายสัปดาห์(เงิน)'!AL13)*100/$I12 -> 0 | AM13: =('ผลงานรายสัปดาห์(เงิน)'!AM13)*100/$I12 -> 0
B14: -4 | C14: งานวัสดุปูพื้น | D14: เหมาจ่าย | E14: 1 | F14: =แผนการก่อสร้าง!G19 -> 0 | G14: =แผนการก่อสร้าง!H19 -> 0 | H14: 789372 | I14: 789372 | J14: 0.33098027 | O14: งานวัสดุปูพื้น
L15: =('ผลงานรายสัปดาห์(เงิน)'!L15)*100/$I14 -> 0 | M15: =('ผลงานรายสัปดาห์(เงิน)'!M15)*100/$I14 -> 0 | P15: =('ผลงานรายสัปดาห์(เงิน)'!P15)*100/$I14 -> 0 | Q15: =('ผลงานรายสัปดาห์(เงิน)'!Q15)*100/$I14 -> 0 | R15: =('ผลงานรายสัปดาห์(เงิน)'!R15)*100/$I14 -> 0 | S15: =('ผลงานรายสัปดาห์(เงิน)'!S15)*100/$I14 -> 0 | T15: =SUM(P15:S15) -> 0 | U15: =('ผลงานรายสัปดาห์(เงิน)'!U15)*100/$I14 -> 0 | V15: =('ผลงานรายสัปดาห์(เงิน)'!V15)*100/$I14 -> 0 | W15: =('ผลงานรายสัปดาห์(เงิน)'!W15)*100/$I14 -> 0 | X15: =('ผลงานรายสัปดาห์(เงิน)'!X15)*100/$I14 -> 0 | Y15: =SUM(U15:X15) -> 0 | Z15: =('ผลงานรายสัปดาห์(เงิน)'!Z15)*100/$I14 -> 0 | AA15: =('ผลงานรายสัปดาห์(เงิน)'!AA15)*100/$I14 -> 0 | AB15: =('ผลงานรายสัปดาห์(เงิน)'!AB15)*100/$I14 -> 0 | AC15: =('ผลงานรายสัปดาห์(เงิน)'!AC15)*100/$I14 -> 0 | AD15: =SUM(Z15:AC15) -> 0 | AE15: =('ผลงานรายสัปดาห์(เงิน)'!AE15)*100/$I14 -> 0 | AF15: =('ผลงานรายสัปดาห์(เงิน)'!AF15)*100/$I14 -> 0 | AG15: =('ผลงานรายสัปดาห์(เงิน)'!AG15)*100/$I14 -> 0 | AH15: =('ผลงานรายสัปดาห์(เงิน)'!AH15)*100/$I14 -> 0 | AI15: =SUM(AE15:AH15) -> 0 | AJ15: =('ผลงานรายสัปดาห์(เงิน)'!AJ15)*100/$I14 -> 0 | AK15: =('ผลงานรายสัปดาห์(เงิน)'!AK15)*100/$I14 -> 0 | AL15: =('ผลงานรายสัปดาห์(เงิน)'!AL15)*100/$I14 -> 0 | AM15: =('ผลงานรายสัปดาห์(เงิน)'!AM15)*100/$I14 -> 0
B16: 1.2 | C16: งานเขื่อนป้องกันตลิ่ง แบบที่ 2 | D16: เหมาจ่าย | E16: 1 | F16: =แผนการก่อสร้าง!G21 -> 0.00348 | G16: =แผนการก่อสร้าง!H21 -> 0.348 | H16: 5004503 | I16: 5004503 | J16: 2.0983665 | O16: งานเขื่อนป้องกันตลิ่ง แบบที่ 2
L17: =('ผลงานรายสัปดาห์(เงิน)'!L17)*100/$I16 -> 0.34756698 | M17: =('ผลงานรายสัปดาห์(เงิน)'!M17)*100/$I16 -> 0.34756698 | P17: =('ผลงานรายสัปดาห์(เงิน)'!P17)*100/$I16 -> 0 | Q17: =('ผลงานรายสัปดาห์(เงิน)'!Q17)*100/$I16 -> 0 | R17: =('ผลงานรายสัปดาห์(เงิน)'!R17)*100/$I16 -> 0 | S17: =('ผลงานรายสัปดาห์(เงิน)'!S17)*100/$I16 -> 0.34756698 | T17: 0.348 | U17: =('ผลงานรายสัปดาห์(เงิน)'!U17)*100/$I16 -> 0 | V17: =('ผลงานรายสัปดาห์(เงิน)'!V17)*100/$I16 -> 0 | W17: =('ผลงานรายสัปดาห์(เงิน)'!W17)*100/$I16 -> 0 | X17: =('ผลงานรายสัปดาห์(เงิน)'!X17)*100/$I16 -> 0 | Y17: =SUM(U17:X17) -> 0 | Z17: =('ผลงานรายสัปดาห์(เงิน)'!Z17)*100/$I16 -> 0 | AA17: =('ผลงานรายสัปดาห์(เงิน)'!AA17)*100/$I16 -> 0 | AB17: =('ผลงานรายสัปดาห์(เงิน)'!AB17)*100/$I16 -> 0 | AC17: =('ผลงานรายสัปดาห์(เงิน)'!AC17)*100/$I16 -> 0 | AD17: =SUM(Z17:AC17) -> 0 | AE17: =('ผลงานรายสัปดาห์(เงิน)'!AE17)*100/$I16 -> 0 | AF17: =('ผลงานรายสัปดาห์(เงิน)'!AF17)*100/$I16 -> 0 | AG17: =('ผลงานรายสัปดาห์(เงิน)'!AG17)*100/$I16 -> 0 | AH17: =('ผลงานรายสัปดาห์(เงิน)'!AH17)*100/$I16 -> 0 | AI17: =SUM(AE17:AH17) -> 0 | AJ17: =('ผลงานรายสัปดาห์(เงิน)'!AJ17)*100/$I16 -> 0 | AK17: =('ผลงานรายสัปดาห์(เงิน)'!AK17)*100/$I16 -> 0 | AL17: =('ผลงานรายสัปดาห์(เงิน)'!AL17)*100/$I16 -> 0 | AM17: =('ผลงานรายสัปดาห์(เงิน)'!AM17)*100/$I16 -> 0
B18: -1 | C18: งานคาน | D18: เหมาจ่าย | E18: 1 | F18: =แผนการก่อสร้าง!G23 -> 0 | G18: =แผนการก่อสร้าง!H23 -> 0 | H18: 1136018 | I18: 1136018 | J18: 0.47632744 | O18: งานคาน
L19: =('ผลงานรายสัปดาห์(เงิน)'!L19)*100/$I18 -> 0 | M19: =('ผลงานรายสัปดาห์(เงิน)'!M19)*100/$I18 -> 0 | P19: =('ผลงานรายสัปดาห์(เงิน)'!P19)*100/$I18 -> 0 | Q19: =('ผลงานรายสัปดาห์(เงิน)'!Q19)*100/$I18 -> 0 | R19: =('ผลงานรายสัปดาห์(เงิน)'!R19)*100/$I18 -> 0 | S19: =('ผลงานรายสัปดาห์(เงิน)'!S19)*100/$I18 -> 0 | T19: =SUM(P19:S19) -> 0 | U19: =('ผลงานรายสัปดาห์(เงิน)'!U19)*100/$I18 -> 0 | V19: =('ผลงานรายสัปดาห์(เงิน)'!V19)*100/$I18 -> 0 | W19: =('ผลงานรายสัปดาห์(เงิน)'!W19)*100/$I18 -> 0 | X19: =('ผลงานรายสัปดาห์(เงิน)'!X19)*100/$I18 -> 0 | Y19: =SUM(U19:X19) -> 0 | Z19: =('ผลงานรายสัปดาห์(เงิน)'!Z19)*100/$I18 -> 0 | AA19: =('ผลงานรายสัปดาห์(เงิน)'!AA19)*100/$I18 -> 0 | AB19: =('ผลงานรายสัปดาห์(เงิน)'!AB19)*100/$I18 -> 0 | AC19: =('ผลงานรายสัปดาห์(เงิน)'!AC19)*100/$I18 -> 0 | AD19: =SUM(Z19:AC19) -> 0 | AE19: =('ผลงานรายสัปดาห์(เงิน)'!AE19)*100/$I18 -> 0 | AF19: =('ผลงานรายสัปดาห์(เงิน)'!AF19)*100/$I18 -> 0 | AG19: =('ผลงานรายสัปดาห์(เงิน)'!AG19)*100/$I18 -> 0 | AH19: =('ผลงานรายสัปดาห์(เงิน)'!AH19)*100/$I18 -> 0 | AI19: =SUM(AE19:AH19) -> 0 | AJ19: =('ผลงานรายสัปดาห์(เงิน)'!AJ19)*100/$I18 -> 0 | AK19: =('ผลงานรายสัปดาห์(เงิน)'!AK19)*100/$I18 -> 0 | AL19: =('ผลงานรายสัปดาห์(เงิน)'!AL19)*100/$I18 -> 0 | AM19: =('ผลงานรายสัปดาห์(เงิน)'!AM19)*100/$I18 -> 0
B20: -2 | C20: งานราวกันตก | D20: เหมาจ่าย | E20: 1 | F20: =แผนการก่อสร้าง!G25 -> 0 | G20: =แผนการก่อสร้าง!H25 -> 0 | H20: 528774 | I20: 528774 | J20: 0.22171265 | O20: งานราวกันตก
L21: =('ผลงานรายสัปดาห์(เงิน)'!L21)*100/$I20 -> 0 | M21: =('ผลงานรายสัปดาห์(เงิน)'!M21)*100/$I20 -> 0 | P21: =('ผลงานรายสัปดาห์(เงิน)'!P21)*100/$I20 -> 0 | Q21: =('ผลงานรายสัปดาห์(เงิน)'!Q21)*100/$I20 -> 0 | R21: =('ผลงานรายสัปดาห์(เงิน)'!R21)*100/$I20 -> 0 | S21: =('ผลงานรายสัปดาห์(เงิน)'!S21)*100/$I20 -> 0 | T21: =SUM(P21:S21) -> 0 | U21: =('ผลงานรายสัปดาห์(เงิน)'!U21)*100/$I20 -> 0 | V21: =('ผลงานรายสัปดาห์(เงิน)'!V21)*100/$I20 -> 0 | W21: =('ผลงานรายสัปดาห์(เงิน)'!W21)*100/$I20 -> 0 | X21: =('ผลงานรายสัปดาห์(เงิน)'!X21)*100/$I20 -> 0 | Y21: =SUM(U21:X21) -> 0 | Z21: =('ผลงานรายสัปดาห์(เงิน)'!Z21)*100/$I20 -> 0 | AA21: =('ผลงานรายสัปดาห์(เงิน)'!AA21)*100/$I20 -> 0 | AB21: =('ผลงานรายสัปดาห์(เงิน)'!AB21)*100/$I20 -> 0 | AC21: =('ผลงานรายสัปดาห์(เงิน)'!AC21)*100/$I20 -> 0 | AD21: =SUM(Z21:AC21) -> 0 | AE21: =('ผลงานรายสัปดาห์(เงิน)'!AE21)*100/$I20 -> 0 | AF21: =('ผลงานรายสัปดาห์(เงิน)'!AF21)*100/$I20 -> 0 | AG21: =('ผลงานรายสัปดาห์(เงิน)'!AG21)*100/$I20 -> 0 | AH21: =('ผลงานรายสัปดาห์(เงิน)'!AH21)*100/$I20 -> 0 | AI21: =SUM(AE21:AH21) -> 0 | AJ21: =('ผลงานรายสัปดาห์(เงิน)'!AJ21)*100/$I20 -> 0 | AK21: =('ผลงานรายสัปดาห์(เงิน)'!AK21)*100/$I20 -> 0 | AL21: =('ผลงานรายสัปดาห์(เงิน)'!AL21)*100/$I20 -> 0 | AM21: =('ผลงานรายสัปดาห์(เงิน)'!AM21)*100/$I20 -> 0
B22: -3 | C22: งานระบายน้ำหลังเขื่อน | D22: เหมาจ่าย | E22: 1 | F22: =แผนการก่อสร้าง!G27 -> 0 | G22: =แผนการก่อสร้าง!H27 -> 0 | H22: 160623 | I22: 160623 | J22: 0.06734853 | O22: งานระบายน้ำหลังเขื่อน
